2020-05-06 14:20:12 WARNING (MainThread) [homeassistant.loader] You are using a custom integration for hacs which has not been tested by Home Assistant. This component might cause stability problems, be sure to disable it if you experience issues with Home Assistant.
2020-05-06 14:20:24 WARNING (MainThread) [homeassistant.loader] You are using a custom integration for bom_forecast which has not been tested by Home Assistant. This component might cause stability problems, be sure to disable it if you experience issues with Home Assistant.
2020-05-06 14:20:30 WARNING (MainThread) [homeassistant.components.mobile_app.notify] Found duplicate device name Aruna Gupta’s iPhone
2020-05-06 14:20:30 WARNING (MainThread) [homeassistant.components.mobile_app.notify] Found duplicate device name Aruna Gupta’s iPhone
2020-05-06 14:20:48 WARNING (MainThread) [homeassistant.helpers.translation] hacs: the '.translations' directory has been moved, the new name is 'translations', starting with Home Assistant 0.111 your translations will no longer load if you do not move/rename this 
2020-05-06 14:20:48 WARNING (MainThread) [homeassistant.helpers.translation] hacs: the '.translations' directory has been moved, the new name is 'translations', starting with Home Assistant 0.111 your translations will no longer load if you do not move/rename this 
2020-05-06 14:20:48 WARNING (MainThread) [homeassistant.helpers.translation] hacs: the '.translations' directory has been moved, the new name is 'translations', starting with Home Assistant 0.111 your translations will no longer load if you do not move/rename this 
2020-05-06 14:21:07 WARNING (MainThread) [homeassistant.components.http.ban] Login attempt or request with invalid authentication from 192.168.20.68
2020-05-06 14:21:10 WARNING (MainThread) [homeassistant.components.http.ban] Login attempt or request with invalid authentication from 192.168.20.68
2020-05-06 14:21:10 WARNING (MainThread) [homeassistant.components.http.ban] Login attempt or request with invalid authentication from 192.168.20.68
2020-05-06 14:21:20 WARNING (MainThread) [homeassistant.components.http.ban] Login attempt or request with invalid authentication from 192.168.20.68
2020-05-06 14:21:29 WARNING (MainThread) [homeassistant.components.http.ban] Login attempt or request with invalid authentication from 192.168.20.68
2020-05-06 14:39:01 ERROR (MainThread) [aiohttp.server] Error handling request
Traceback (most recent call last):
  File "/usr/local/lib/python3.7/site-packages/urllib3/connection.py", line 160, in _new_conn
    (self._dns_host, self.port), self.timeout, **extra_kw
  File "/usr/local/lib/python3.7/site-packages/urllib3/util/connection.py", line 84, in create_connection
    raise err
  File "/usr/local/lib/python3.7/site-packages/urllib3/util/connection.py", line 74, in create_connection
    sock.connect(sa)
ConnectionRefusedError: [Errno 111] Connection refused

During handling of the above exception, another exception occurred:

Traceback (most recent call last):
  File "/usr/local/lib/python3.7/site-packages/urllib3/connectionpool.py", line 677, in urlopen
    chunked=chunked,
  File "/usr/local/lib/python3.7/site-packages/urllib3/connectionpool.py", line 392, in _make_request
    conn.request(method, url, **httplib_request_kw)
  File "/usr/local/lib/python3.7/http/client.py", line 1252, in request
    self._send_request(method, url, body, headers, encode_chunked)
  File "/usr/local/lib/python3.7/http/client.py", line 1298, in _send_request
    self.endheaders(body, encode_chunked=encode_chunked)
  File "/usr/local/lib/python3.7/http/client.py", line 1247, in endheaders
    self._send_output(message_body, encode_chunked=encode_chunked)
  File "/usr/local/lib/python3.7/http/client.py", line 1026, in _send_output
    self.send(msg)
  File "/usr/local/lib/python3.7/http/client.py", line 966, in send
    self.connect()
  File "/usr/local/lib/python3.7/site-packages/urllib3/connection.py", line 187, in connect
    conn = self._new_conn()
  File "/usr/local/lib/python3.7/site-packages/urllib3/connection.py", line 172, in _new_conn
    self, "Failed to establish a new connection: %s" % e
urllib3.exceptions.NewConnectionError: <urllib3.connection.HTTPConnection object at 0x69f7edb0>: Failed to establish a new connection: [Errno 111] Connection refused

During handling of the above exception, another exception occurred:

Traceback (most recent call last):
  File "/usr/local/lib/python3.7/site-packages/requests/adapters.py", line 449, in send
    timeout=timeout
  File "/usr/local/lib/python3.7/site-packages/urllib3/connectionpool.py", line 725, in urlopen
    method, url, error=e, _pool=self, _stacktrace=sys.exc_info()[2]
  File "/usr/local/lib/python3.7/site-packages/urllib3/util/retry.py", line 439, in increment
    raise MaxRetryError(_pool, url, error or ResponseError(cause))
urllib3.exceptions.MaxRetryError: HTTPConnectionPool(host='192.168.20.84', port=8080): Max retries exceeded with url: /?action=stream (Caused by NewConnectionError('<urllib3.connection.HTTPConnection object at 0x69f7edb0>: Failed to establish a new connection: [Errno 111] Connection refused'))

During handling of the above exception, another exception occurred:

Traceback (most recent call last):
  File "/usr/local/lib/python3.7/site-packages/aiohttp/web_protocol.py", line 418, in start
    resp = await task
  File "/usr/local/lib/python3.7/site-packages/aiohttp/web_app.py", line 458, in _handle
    resp = await handler(request)
  File "/usr/local/lib/python3.7/site-packages/aiohttp/web_middlewares.py", line 119, in impl
    return await handler(request)
  File "/usr/src/homeassistant/homeassistant/components/http/real_ip.py", line 39, in real_ip_middleware
    return await handler(request)
  File "/usr/src/homeassistant/homeassistant/components/http/ban.py", line 73, in ban_middleware
    return await handler(request)
  File "/usr/src/homeassistant/homeassistant/components/http/auth.py", line 127, in auth_middleware
    return await handler(request)
  File "/usr/src/homeassistant/homeassistant/components/http/view.py", line 125, in handle
    result = await result
  File "/usr/src/homeassistant/homeassistant/components/camera/__init__.py", line 490, in get
    return await self.handle(request, camera)
  File "/usr/src/homeassistant/homeassistant/components/camera/__init__.py", line 507, in handle
    image = await camera.async_camera_image()
  File "/usr/src/homeassistant/homeassistant/components/mjpeg/camera.py", line 113, in async_camera_image
    image = await self.hass.async_add_job(self.camera_image)
  File "/usr/local/lib/python3.7/concurrent/futures/thread.py", line 57, in run
    result = self.fn(*self.args, **self.kwargs)
  File "/usr/src/homeassistant/homeassistant/components/mjpeg/camera.py", line 145, in camera_image
    req = requests.get(self._mjpeg_url, stream=True, timeout=10)
  File "/usr/local/lib/python3.7/site-packages/requests/api.py", line 76, in get
    return request('get', url, params=params, **kwargs)
  File "/usr/local/lib/python3.7/site-packages/requests/api.py", line 61, in request
    return session.request(method=method, url=url, **kwargs)
  File "/usr/local/lib/python3.7/site-packages/requests/sessions.py", line 530, in request
    resp = self.send(prep, **send_kwargs)
  File "/usr/local/lib/python3.7/site-packages/requests/sessions.py", line 643, in send
    r = adapter.send(request, **kwargs)
  File "/usr/local/lib/python3.7/site-packages/requests/adapters.py", line 516, in send
    raise ConnectionError(e, request=request)
requests.exceptions.ConnectionError: HTTPConnectionPool(host='192.168.20.84', port=8080): Max retries exceeded with url: /?action=stream (Caused by NewConnectionError('<urllib3.connection.HTTPConnection object at 0x69f7edb0>: Failed to establish a new connection: [Errno 111] Connection refused'))
2020-05-06 14:39:03 ERROR (MainThread) [aiohttp.server] Error handling request
Traceback (most recent call last):
  File "/usr/local/lib/python3.7/site-packages/urllib3/connection.py", line 160, in _new_conn
    (self._dns_host, self.port), self.timeout, **extra_kw
  File "/usr/local/lib/python3.7/site-packages/urllib3/util/connection.py", line 84, in create_connection
    raise err
  File "/usr/local/lib/python3.7/site-packages/urllib3/util/connection.py", line 74, in create_connection
    sock.connect(sa)
ConnectionRefusedError: [Errno 111] Connection refused

During handling of the above exception, another exception occurred:

Traceback (most recent call last):
  File "/usr/local/lib/python3.7/site-packages/urllib3/connectionpool.py", line 677, in urlopen
    chunked=chunked,
  File "/usr/local/lib/python3.7/site-packages/urllib3/connectionpool.py", line 392, in _make_request
    conn.request(method, url, **httplib_request_kw)
  File "/usr/local/lib/python3.7/http/client.py", line 1252, in request
    self._send_request(method, url, body, headers, encode_chunked)
  File "/usr/local/lib/python3.7/http/client.py", line 1298, in _send_request
    self.endheaders(body, encode_chunked=encode_chunked)
  File "/usr/local/lib/python3.7/http/client.py", line 1247, in endheaders
    self._send_output(message_body, encode_chunked=encode_chunked)
  File "/usr/local/lib/python3.7/http/client.py", line 1026, in _send_output
    self.send(msg)
  File "/usr/local/lib/python3.7/http/client.py", line 966, in send
    self.connect()
  File "/usr/local/lib/python3.7/site-packages/urllib3/connection.py", line 187, in connect
    conn = self._new_conn()
  File "/usr/local/lib/python3.7/site-packages/urllib3/connection.py", line 172, in _new_conn
    self, "Failed to establish a new connection: %s" % e
urllib3.exceptions.NewConnectionError: <urllib3.connection.HTTPConnection object at 0x689a7910>: Failed to establish a new connection: [Errno 111] Connection refused

During handling of the above exception, another exception occurred:

Traceback (most recent call last):
  File "/usr/local/lib/python3.7/site-packages/requests/adapters.py", line 449, in send
    timeout=timeout
  File "/usr/local/lib/python3.7/site-packages/urllib3/connectionpool.py", line 725, in urlopen
    method, url, error=e, _pool=self, _stacktrace=sys.exc_info()[2]
  File "/usr/local/lib/python3.7/site-packages/urllib3/util/retry.py", line 439, in increment
    raise MaxRetryError(_pool, url, error or ResponseError(cause))
urllib3.exceptions.MaxRetryError: HTTPConnectionPool(host='192.168.20.84', port=8080): Max retries exceeded with url: /?action=stream (Caused by NewConnectionError('<urllib3.connection.HTTPConnection object at 0x689a7910>: Failed to establish a new connection: [Errno 111] Connection refused'))

During handling of the above exception, another exception occurred:

Traceback (most recent call last):
  File "/usr/local/lib/python3.7/site-packages/aiohttp/web_protocol.py", line 418, in start
    resp = await task
  File "/usr/local/lib/python3.7/site-packages/aiohttp/web_app.py", line 458, in _handle
    resp = await handler(request)
  File "/usr/local/lib/python3.7/site-packages/aiohttp/web_middlewares.py", line 119, in impl
    return await handler(request)
  File "/usr/src/homeassistant/homeassistant/components/http/real_ip.py", line 39, in real_ip_middleware
    return await handler(request)
  File "/usr/src/homeassistant/homeassistant/components/http/ban.py", line 73, in ban_middleware
    return await handler(request)
  File "/usr/src/homeassistant/homeassistant/components/http/auth.py", line 127, in auth_middleware
    return await handler(request)
  File "/usr/src/homeassistant/homeassistant/components/http/view.py", line 125, in handle
    result = await result
  File "/usr/src/homeassistant/homeassistant/components/camera/__init__.py", line 490, in get
    return await self.handle(request, camera)
  File "/usr/src/homeassistant/homeassistant/components/camera/__init__.py", line 507, in handle
    image = await camera.async_camera_image()
  File "/usr/src/homeassistant/homeassistant/components/mjpeg/camera.py", line 113, in async_camera_image
    image = await self.hass.async_add_job(self.camera_image)
  File "/usr/local/lib/python3.7/concurrent/futures/thread.py", line 57, in run
    result = self.fn(*self.args, **self.kwargs)
  File "/usr/src/homeassistant/homeassistant/components/mjpeg/camera.py", line 145, in camera_image
    req = requests.get(self._mjpeg_url, stream=True, timeout=10)
  File "/usr/local/lib/python3.7/site-packages/requests/api.py", line 76, in get
    return request('get', url, params=params, **kwargs)
  File "/usr/local/lib/python3.7/site-packages/requests/api.py", line 61, in request
    return session.request(method=method, url=url, **kwargs)
  File "/usr/local/lib/python3.7/site-packages/requests/sessions.py", line 530, in request
    resp = self.send(prep, **send_kwargs)
  File "/usr/local/lib/python3.7/site-packages/requests/sessions.py", line 643, in send
    r = adapter.send(request, **kwargs)
  File "/usr/local/lib/python3.7/site-packages/requests/adapters.py", line 516, in send
    raise ConnectionError(e, request=request)
requests.exceptions.ConnectionError: HTTPConnectionPool(host='192.168.20.84', port=8080): Max retries exceeded with url: /?action=stream (Caused by NewConnectionError('<urllib3.connection.HTTPConnection object at 0x689a7910>: Failed to establish a new connection: [Errno 111] Connection refused'))
2020-05-06 14:39:11 ERROR (MainThread) [aiohttp.server] Error handling request
Traceback (most recent call last):
  File "/usr/local/lib/python3.7/site-packages/urllib3/connection.py", line 160, in _new_conn
    (self._dns_host, self.port), self.timeout, **extra_kw
  File "/usr/local/lib/python3.7/site-packages/urllib3/util/connection.py", line 84, in create_connection
    raise err
  File "/usr/local/lib/python3.7/site-packages/urllib3/util/connection.py", line 74, in create_connection
    sock.connect(sa)
ConnectionRefusedError: [Errno 111] Connection refused

During handling of the above exception, another exception occurred:

Traceback (most recent call last):
  File "/usr/local/lib/python3.7/site-packages/urllib3/connectionpool.py", line 677, in urlopen
    chunked=chunked,
  File "/usr/local/lib/python3.7/site-packages/urllib3/connectionpool.py", line 392, in _make_request
    conn.request(method, url, **httplib_request_kw)
  File "/usr/local/lib/python3.7/http/client.py", line 1252, in request
    self._send_request(method, url, body, headers, encode_chunked)
  File "/usr/local/lib/python3.7/http/client.py", line 1298, in _send_request
    self.endheaders(body, encode_chunked=encode_chunked)
  File "/usr/local/lib/python3.7/http/client.py", line 1247, in endheaders
    self._send_output(message_body, encode_chunked=encode_chunked)
  File "/usr/local/lib/python3.7/http/client.py", line 1026, in _send_output
    self.send(msg)
  File "/usr/local/lib/python3.7/http/client.py", line 966, in send
    self.connect()
  File "/usr/local/lib/python3.7/site-packages/urllib3/connection.py", line 187, in connect
    conn = self._new_conn()
  File "/usr/local/lib/python3.7/site-packages/urllib3/connection.py", line 172, in _new_conn
    self, "Failed to establish a new connection: %s" % e
urllib3.exceptions.NewConnectionError: <urllib3.connection.HTTPConnection object at 0x6a5b8d30>: Failed to establish a new connection: [Errno 111] Connection refused

During handling of the above exception, another exception occurred:

Traceback (most recent call last):
  File "/usr/local/lib/python3.7/site-packages/requests/adapters.py", line 449, in send
    timeout=timeout
  File "/usr/local/lib/python3.7/site-packages/urllib3/connectionpool.py", line 725, in urlopen
    method, url, error=e, _pool=self, _stacktrace=sys.exc_info()[2]
  File "/usr/local/lib/python3.7/site-packages/urllib3/util/retry.py", line 439, in increment
    raise MaxRetryError(_pool, url, error or ResponseError(cause))
urllib3.exceptions.MaxRetryError: HTTPConnectionPool(host='192.168.20.84', port=8080): Max retries exceeded with url: /?action=stream (Caused by NewConnectionError('<urllib3.connection.HTTPConnection object at 0x6a5b8d30>: Failed to establish a new connection: [Errno 111] Connection refused'))

During handling of the above exception, another exception occurred:

Traceback (most recent call last):
  File "/usr/local/lib/python3.7/site-packages/aiohttp/web_protocol.py", line 418, in start
    resp = await task
  File "/usr/local/lib/python3.7/site-packages/aiohttp/web_app.py", line 458, in _handle
    resp = await handler(request)
  File "/usr/local/lib/python3.7/site-packages/aiohttp/web_middlewares.py", line 119, in impl
    return await handler(request)
  File "/usr/src/homeassistant/homeassistant/components/http/real_ip.py", line 39, in real_ip_middleware
    return await handler(request)
  File "/usr/src/homeassistant/homeassistant/components/http/ban.py", line 73, in ban_middleware
    return await handler(request)
  File "/usr/src/homeassistant/homeassistant/components/http/auth.py", line 127, in auth_middleware
    return await handler(request)
  File "/usr/src/homeassistant/homeassistant/components/http/view.py", line 125, in handle
    result = await result
  File "/usr/src/homeassistant/homeassistant/components/camera/__init__.py", line 490, in get
    return await self.handle(request, camera)
  File "/usr/src/homeassistant/homeassistant/components/camera/__init__.py", line 507, in handle
    image = await camera.async_camera_image()
  File "/usr/src/homeassistant/homeassistant/components/mjpeg/camera.py", line 113, in async_camera_image
    image = await self.hass.async_add_job(self.camera_image)
  File "/usr/local/lib/python3.7/concurrent/futures/thread.py", line 57, in run
    result = self.fn(*self.args, **self.kwargs)
  File "/usr/src/homeassistant/homeassistant/components/mjpeg/camera.py", line 145, in camera_image
    req = requests.get(self._mjpeg_url, stream=True, timeout=10)
  File "/usr/local/lib/python3.7/site-packages/requests/api.py", line 76, in get
    return request('get', url, params=params, **kwargs)
  File "/usr/local/lib/python3.7/site-packages/requests/api.py", line 61, in request
    return session.request(method=method, url=url, **kwargs)
  File "/usr/local/lib/python3.7/site-packages/requests/sessions.py", line 530, in request
    resp = self.send(prep, **send_kwargs)
  File "/usr/local/lib/python3.7/site-packages/requests/sessions.py", line 643, in send
    r = adapter.send(request, **kwargs)
  File "/usr/local/lib/python3.7/site-packages/requests/adapters.py", line 516, in send
    raise ConnectionError(e, request=request)
requests.exceptions.ConnectionError: HTTPConnectionPool(host='192.168.20.84', port=8080): Max retries exceeded with url: /?action=stream (Caused by NewConnectionError('<urllib3.connection.HTTPConnection object at 0x6a5b8d30>: Failed to establish a new connection: [Errno 111] Connection refused'))
2020-05-06 14:39:17 ERROR (MainThread) [frontend.js.latest.202004272] http://192.168.20.84:8123/frontend_latest/chunk.9cedb8f1a54a4b78de8b.js:2813:193691 Uncaught YAMLException: unacceptable kind of an object to dump [object Undefined]
2020-05-06 14:39:57 ERROR (MainThread) [aiohttp.server] Error handling request
Traceback (most recent call last):
  File "/usr/local/lib/python3.7/site-packages/urllib3/connection.py", line 160, in _new_conn
    (self._dns_host, self.port), self.timeout, **extra_kw
  File "/usr/local/lib/python3.7/site-packages/urllib3/util/connection.py", line 84, in create_connection
    raise err
  File "/usr/local/lib/python3.7/site-packages/urllib3/util/connection.py", line 74, in create_connection
    sock.connect(sa)
ConnectionRefusedError: [Errno 111] Connection refused

During handling of the above exception, another exception occurred:

Traceback (most recent call last):
  File "/usr/local/lib/python3.7/site-packages/urllib3/connectionpool.py", line 677, in urlopen
    chunked=chunked,
  File "/usr/local/lib/python3.7/site-packages/urllib3/connectionpool.py", line 392, in _make_request
    conn.request(method, url, **httplib_request_kw)
  File "/usr/local/lib/python3.7/http/client.py", line 1252, in request
    self._send_request(method, url, body, headers, encode_chunked)
  File "/usr/local/lib/python3.7/http/client.py", line 1298, in _send_request
    self.endheaders(body, encode_chunked=encode_chunked)
  File "/usr/local/lib/python3.7/http/client.py", line 1247, in endheaders
    self._send_output(message_body, encode_chunked=encode_chunked)
  File "/usr/local/lib/python3.7/http/client.py", line 1026, in _send_output
    self.send(msg)
  File "/usr/local/lib/python3.7/http/client.py", line 966, in send
    self.connect()
  File "/usr/local/lib/python3.7/site-packages/urllib3/connection.py", line 187, in connect
    conn = self._new_conn()
  File "/usr/local/lib/python3.7/site-packages/urllib3/connection.py", line 172, in _new_conn
    self, "Failed to establish a new connection: %s" % e
urllib3.exceptions.NewConnectionError: <urllib3.connection.HTTPConnection object at 0x6a82f850>: Failed to establish a new connection: [Errno 111] Connection refused

During handling of the above exception, another exception occurred:

Traceback (most recent call last):
  File "/usr/local/lib/python3.7/site-packages/requests/adapters.py", line 449, in send
    timeout=timeout
  File "/usr/local/lib/python3.7/site-packages/urllib3/connectionpool.py", line 725, in urlopen
    method, url, error=e, _pool=self, _stacktrace=sys.exc_info()[2]
  File "/usr/local/lib/python3.7/site-packages/urllib3/util/retry.py", line 439, in increment
    raise MaxRetryError(_pool, url, error or ResponseError(cause))
urllib3.exceptions.MaxRetryError: HTTPConnectionPool(host='192.168.20.84', port=8080): Max retries exceeded with url: /?action=stream (Caused by NewConnectionError('<urllib3.connection.HTTPConnection object at 0x6a82f850>: Failed to establish a new connection: [Errno 111] Connection refused'))

During handling of the above exception, another exception occurred:

Traceback (most recent call last):
  File "/usr/local/lib/python3.7/site-packages/aiohttp/web_protocol.py", line 418, in start
    resp = await task
  File "/usr/local/lib/python3.7/site-packages/aiohttp/web_app.py", line 458, in _handle
    resp = await handler(request)
  File "/usr/local/lib/python3.7/site-packages/aiohttp/web_middlewares.py", line 119, in impl
    return await handler(request)
  File "/usr/src/homeassistant/homeassistant/components/http/real_ip.py", line 39, in real_ip_middleware
    return await handler(request)
  File "/usr/src/homeassistant/homeassistant/components/http/ban.py", line 73, in ban_middleware
    return await handler(request)
  File "/usr/src/homeassistant/homeassistant/components/http/auth.py", line 127, in auth_middleware
    return await handler(request)
  File "/usr/src/homeassistant/homeassistant/components/http/view.py", line 125, in handle
    result = await result
  File "/usr/src/homeassistant/homeassistant/components/camera/__init__.py", line 490, in get
    return await self.handle(request, camera)
  File "/usr/src/homeassistant/homeassistant/components/camera/__init__.py", line 507, in handle
    image = await camera.async_camera_image()
  File "/usr/src/homeassistant/homeassistant/components/mjpeg/camera.py", line 113, in async_camera_image
    image = await self.hass.async_add_job(self.camera_image)
  File "/usr/local/lib/python3.7/concurrent/futures/thread.py", line 57, in run
    result = self.fn(*self.args, **self.kwargs)
  File "/usr/src/homeassistant/homeassistant/components/mjpeg/camera.py", line 145, in camera_image
    req = requests.get(self._mjpeg_url, stream=True, timeout=10)
  File "/usr/local/lib/python3.7/site-packages/requests/api.py", line 76, in get
    return request('get', url, params=params, **kwargs)
  File "/usr/local/lib/python3.7/site-packages/requests/api.py", line 61, in request
    return session.request(method=method, url=url, **kwargs)
  File "/usr/local/lib/python3.7/site-packages/requests/sessions.py", line 530, in request
    resp = self.send(prep, **send_kwargs)
  File "/usr/local/lib/python3.7/site-packages/requests/sessions.py", line 643, in send
    r = adapter.send(request, **kwargs)
  File "/usr/local/lib/python3.7/site-packages/requests/adapters.py", line 516, in send
    raise ConnectionError(e, request=request)
requests.exceptions.ConnectionError: HTTPConnectionPool(host='192.168.20.84', port=8080): Max retries exceeded with url: /?action=stream (Caused by NewConnectionError('<urllib3.connection.HTTPConnection object at 0x6a82f850>: Failed to establish a new connection: [Errno 111] Connection refused'))
2020-05-06 14:40:29 ERROR (MainThread) [aiohttp.server] Error handling request
Traceback (most recent call last):
  File "/usr/local/lib/python3.7/site-packages/urllib3/connection.py", line 160, in _new_conn
    (self._dns_host, self.port), self.timeout, **extra_kw
  File "/usr/local/lib/python3.7/site-packages/urllib3/util/connection.py", line 84, in create_connection
    raise err
  File "/usr/local/lib/python3.7/site-packages/urllib3/util/connection.py", line 74, in create_connection
    sock.connect(sa)
ConnectionRefusedError: [Errno 111] Connection refused

During handling of the above exception, another exception occurred:

Traceback (most recent call last):
  File "/usr/local/lib/python3.7/site-packages/urllib3/connectionpool.py", line 677, in urlopen
    chunked=chunked,
  File "/usr/local/lib/python3.7/site-packages/urllib3/connectionpool.py", line 392, in _make_request
    conn.request(method, url, **httplib_request_kw)
  File "/usr/local/lib/python3.7/http/client.py", line 1252, in request
    self._send_request(method, url, body, headers, encode_chunked)
  File "/usr/local/lib/python3.7/http/client.py", line 1298, in _send_request
    self.endheaders(body, encode_chunked=encode_chunked)
  File "/usr/local/lib/python3.7/http/client.py", line 1247, in endheaders
    self._send_output(message_body, encode_chunked=encode_chunked)
  File "/usr/local/lib/python3.7/http/client.py", line 1026, in _send_output
    self.send(msg)
  File "/usr/local/lib/python3.7/http/client.py", line 966, in send
    self.connect()
  File "/usr/local/lib/python3.7/site-packages/urllib3/connection.py", line 187, in connect
    conn = self._new_conn()
  File "/usr/local/lib/python3.7/site-packages/urllib3/connection.py", line 172, in _new_conn
    self, "Failed to establish a new connection: %s" % e
urllib3.exceptions.NewConnectionError: <urllib3.connection.HTTPConnection object at 0x66cfb350>: Failed to establish a new connection: [Errno 111] Connection refused

During handling of the above exception, another exception occurred:

Traceback (most recent call last):
  File "/usr/local/lib/python3.7/site-packages/requests/adapters.py", line 449, in send
    timeout=timeout
  File "/usr/local/lib/python3.7/site-packages/urllib3/connectionpool.py", line 725, in urlopen
    method, url, error=e, _pool=self, _stacktrace=sys.exc_info()[2]
  File "/usr/local/lib/python3.7/site-packages/urllib3/util/retry.py", line 439, in increment
    raise MaxRetryError(_pool, url, error or ResponseError(cause))
urllib3.exceptions.MaxRetryError: HTTPConnectionPool(host='192.168.20.84', port=8080): Max retries exceeded with url: /?action=stream (Caused by NewConnectionError('<urllib3.connection.HTTPConnection object at 0x66cfb350>: Failed to establish a new connection: [Errno 111] Connection refused'))

During handling of the above exception, another exception occurred:

Traceback (most recent call last):
  File "/usr/local/lib/python3.7/site-packages/aiohttp/web_protocol.py", line 418, in start
    resp = await task
  File "/usr/local/lib/python3.7/site-packages/aiohttp/web_app.py", line 458, in _handle
    resp = await handler(request)
  File "/usr/local/lib/python3.7/site-packages/aiohttp/web_middlewares.py", line 119, in impl
    return await handler(request)
  File "/usr/src/homeassistant/homeassistant/components/http/real_ip.py", line 39, in real_ip_middleware
    return await handler(request)
  File "/usr/src/homeassistant/homeassistant/components/http/ban.py", line 73, in ban_middleware
    return await handler(request)
  File "/usr/src/homeassistant/homeassistant/components/http/auth.py", line 127, in auth_middleware
    return await handler(request)
  File "/usr/src/homeassistant/homeassistant/components/http/view.py", line 125, in handle
    result = await result
  File "/usr/src/homeassistant/homeassistant/components/camera/__init__.py", line 490, in get
    return await self.handle(request, camera)
  File "/usr/src/homeassistant/homeassistant/components/camera/__init__.py", line 507, in handle
    image = await camera.async_camera_image()
  File "/usr/src/homeassistant/homeassistant/components/mjpeg/camera.py", line 113, in async_camera_image
    image = await self.hass.async_add_job(self.camera_image)
  File "/usr/local/lib/python3.7/concurrent/futures/thread.py", line 57, in run
    result = self.fn(*self.args, **self.kwargs)
  File "/usr/src/homeassistant/homeassistant/components/mjpeg/camera.py", line 145, in camera_image
    req = requests.get(self._mjpeg_url, stream=True, timeout=10)
  File "/usr/local/lib/python3.7/site-packages/requests/api.py", line 76, in get
    return request('get', url, params=params, **kwargs)
  File "/usr/local/lib/python3.7/site-packages/requests/api.py", line 61, in request
    return session.request(method=method, url=url, **kwargs)
  File "/usr/local/lib/python3.7/site-packages/requests/sessions.py", line 530, in request
    resp = self.send(prep, **send_kwargs)
  File "/usr/local/lib/python3.7/site-packages/requests/sessions.py", line 643, in send
    r = adapter.send(request, **kwargs)
  File "/usr/local/lib/python3.7/site-packages/requests/adapters.py", line 516, in send
    raise ConnectionError(e, request=request)
requests.exceptions.ConnectionError: HTTPConnectionPool(host='192.168.20.84', port=8080): Max retries exceeded with url: /?action=stream (Caused by NewConnectionError('<urllib3.connection.HTTPConnection object at 0x66cfb350>: Failed to establish a new connection: [Errno 111] Connection refused'))
