2020-04-14 16:08:54 WARNING (MainThread) [homeassistant.loader] You are using a custom integration for hacs which has not been tested by Home Assistant. This component might cause stability problems, be sure to disable it if you experience issues with Home Assistant.
2020-04-14 16:09:10 WARNING (MainThread) [homeassistant.loader] You are using a custom integration for bom_forecast which has not been tested by Home Assistant. This component might cause stability problems, be sure to disable it if you experience issues with Home Assistant.
2020-04-14 16:19:40 ERROR (MainThread) [homeassistant.components.garmin_connect] Unknown error occurred during Garmin Connect get activity request
Traceback (most recent call last):
  File "/usr/local/lib/python3.7/site-packages/urllib3/connectionpool.py", line 672, in urlopen
    chunked=chunked,
  File "/usr/local/lib/python3.7/site-packages/urllib3/connectionpool.py", line 421, in _make_request
    six.raise_from(e, None)
  File "<string>", line 3, in raise_from
  File "/usr/local/lib/python3.7/site-packages/urllib3/connectionpool.py", line 416, in _make_request
    httplib_response = conn.getresponse()
  File "/usr/local/lib/python3.7/http/client.py", line 1344, in getresponse
    response.begin()
  File "/usr/local/lib/python3.7/http/client.py", line 306, in begin
    version, status, reason = self._read_status()
  File "/usr/local/lib/python3.7/http/client.py", line 267, in _read_status
    line = str(self.fp.readline(_MAXLINE + 1), "iso-8859-1")
  File "/usr/local/lib/python3.7/socket.py", line 589, in readinto
    return self._sock.recv_into(b)
  File "/usr/local/lib/python3.7/site-packages/urllib3/contrib/pyopenssl.py", line 318, in recv_into
    raise SocketError(str(e))
OSError: (104, 'ECONNRESET')

During handling of the above exception, another exception occurred:

Traceback (most recent call last):
  File "/usr/local/lib/python3.7/site-packages/requests/adapters.py", line 449, in send
    timeout=timeout
  File "/usr/local/lib/python3.7/site-packages/urllib3/connectionpool.py", line 720, in urlopen
    method, url, error=e, _pool=self, _stacktrace=sys.exc_info()[2]
  File "/usr/local/lib/python3.7/site-packages/urllib3/util/retry.py", line 400, in increment
    raise six.reraise(type(error), error, _stacktrace)
  File "/usr/local/lib/python3.7/site-packages/urllib3/packages/six.py", line 734, in reraise
    raise value.with_traceback(tb)
  File "/usr/local/lib/python3.7/site-packages/urllib3/connectionpool.py", line 672, in urlopen
    chunked=chunked,
  File "/usr/local/lib/python3.7/site-packages/urllib3/connectionpool.py", line 421, in _make_request
    six.raise_from(e, None)
  File "<string>", line 3, in raise_from
  File "/usr/local/lib/python3.7/site-packages/urllib3/connectionpool.py", line 416, in _make_request
    httplib_response = conn.getresponse()
  File "/usr/local/lib/python3.7/http/client.py", line 1344, in getresponse
    response.begin()
  File "/usr/local/lib/python3.7/http/client.py", line 306, in begin
    version, status, reason = self._read_status()
  File "/usr/local/lib/python3.7/http/client.py", line 267, in _read_status
    line = str(self.fp.readline(_MAXLINE + 1), "iso-8859-1")
  File "/usr/local/lib/python3.7/socket.py", line 589, in readinto
    return self._sock.recv_into(b)
  File "/usr/local/lib/python3.7/site-packages/urllib3/contrib/pyopenssl.py", line 318, in recv_into
    raise SocketError(str(e))
urllib3.exceptions.ProtocolError: ('Connection aborted.', OSError("(104, 'ECONNRESET')"))

During handling of the above exception, another exception occurred:

Traceback (most recent call last):
  File "/usr/src/homeassistant/homeassistant/components/garmin_connect/__init__.py", line 98, in async_update
    self.data = self.client.get_stats_and_body(today.isoformat())
  File "/usr/local/lib/python3.7/site-packages/garminconnect/__init__.py", line 146, in get_stats_and_body
    return ({**self.get_stats(cdate), **self.get_body_composition(cdate)})
  File "/usr/local/lib/python3.7/site-packages/garminconnect/__init__.py", line 155, in get_stats
    response = self.req.get(acturl, headers=self.headers)
  File "/usr/local/lib/python3.7/site-packages/requests/sessions.py", line 543, in get
    return self.request('GET', url, **kwargs)
  File "/usr/local/lib/python3.7/site-packages/requests/sessions.py", line 530, in request
    resp = self.send(prep, **send_kwargs)
  File "/usr/local/lib/python3.7/site-packages/requests/sessions.py", line 643, in send
    r = adapter.send(request, **kwargs)
  File "/usr/local/lib/python3.7/site-packages/requests/adapters.py", line 498, in send
    raise ConnectionError(err, request=request)
requests.exceptions.ConnectionError: ('Connection aborted.', OSError("(104, 'ECONNRESET')"))
2020-04-14 16:40:20 ERROR (MainThread) [homeassistant.components.garmin_connect] Unknown error occurred during Garmin Connect get activity request
Traceback (most recent call last):
  File "/usr/local/lib/python3.7/site-packages/urllib3/connectionpool.py", line 672, in urlopen
    chunked=chunked,
  File "/usr/local/lib/python3.7/site-packages/urllib3/connectionpool.py", line 421, in _make_request
    six.raise_from(e, None)
  File "<string>", line 3, in raise_from
  File "/usr/local/lib/python3.7/site-packages/urllib3/connectionpool.py", line 416, in _make_request
    httplib_response = conn.getresponse()
  File "/usr/local/lib/python3.7/http/client.py", line 1344, in getresponse
    response.begin()
  File "/usr/local/lib/python3.7/http/client.py", line 306, in begin
    version, status, reason = self._read_status()
  File "/usr/local/lib/python3.7/http/client.py", line 267, in _read_status
    line = str(self.fp.readline(_MAXLINE + 1), "iso-8859-1")
  File "/usr/local/lib/python3.7/socket.py", line 589, in readinto
    return self._sock.recv_into(b)
  File "/usr/local/lib/python3.7/site-packages/urllib3/contrib/pyopenssl.py", line 318, in recv_into
    raise SocketError(str(e))
OSError: (104, 'ECONNRESET')

During handling of the above exception, another exception occurred:

Traceback (most recent call last):
  File "/usr/local/lib/python3.7/site-packages/requests/adapters.py", line 449, in send
    timeout=timeout
  File "/usr/local/lib/python3.7/site-packages/urllib3/connectionpool.py", line 720, in urlopen
    method, url, error=e, _pool=self, _stacktrace=sys.exc_info()[2]
  File "/usr/local/lib/python3.7/site-packages/urllib3/util/retry.py", line 400, in increment
    raise six.reraise(type(error), error, _stacktrace)
  File "/usr/local/lib/python3.7/site-packages/urllib3/packages/six.py", line 734, in reraise
    raise value.with_traceback(tb)
  File "/usr/local/lib/python3.7/site-packages/urllib3/connectionpool.py", line 672, in urlopen
    chunked=chunked,
  File "/usr/local/lib/python3.7/site-packages/urllib3/connectionpool.py", line 421, in _make_request
    six.raise_from(e, None)
  File "<string>", line 3, in raise_from
  File "/usr/local/lib/python3.7/site-packages/urllib3/connectionpool.py", line 416, in _make_request
    httplib_response = conn.getresponse()
  File "/usr/local/lib/python3.7/http/client.py", line 1344, in getresponse
    response.begin()
  File "/usr/local/lib/python3.7/http/client.py", line 306, in begin
    version, status, reason = self._read_status()
  File "/usr/local/lib/python3.7/http/client.py", line 267, in _read_status
    line = str(self.fp.readline(_MAXLINE + 1), "iso-8859-1")
  File "/usr/local/lib/python3.7/socket.py", line 589, in readinto
    return self._sock.recv_into(b)
  File "/usr/local/lib/python3.7/site-packages/urllib3/contrib/pyopenssl.py", line 318, in recv_into
    raise SocketError(str(e))
urllib3.exceptions.ProtocolError: ('Connection aborted.', OSError("(104, 'ECONNRESET')"))

During handling of the above exception, another exception occurred:

Traceback (most recent call last):
  File "/usr/src/homeassistant/homeassistant/components/garmin_connect/__init__.py", line 98, in async_update
    self.data = self.client.get_stats_and_body(today.isoformat())
  File "/usr/local/lib/python3.7/site-packages/garminconnect/__init__.py", line 146, in get_stats_and_body
    return ({**self.get_stats(cdate), **self.get_body_composition(cdate)})
  File "/usr/local/lib/python3.7/site-packages/garminconnect/__init__.py", line 155, in get_stats
    response = self.req.get(acturl, headers=self.headers)
  File "/usr/local/lib/python3.7/site-packages/requests/sessions.py", line 543, in get
    return self.request('GET', url, **kwargs)
  File "/usr/local/lib/python3.7/site-packages/requests/sessions.py", line 530, in request
    resp = self.send(prep, **send_kwargs)
  File "/usr/local/lib/python3.7/site-packages/requests/sessions.py", line 643, in send
    r = adapter.send(request, **kwargs)
  File "/usr/local/lib/python3.7/site-packages/requests/adapters.py", line 498, in send
    raise ConnectionError(err, request=request)
requests.exceptions.ConnectionError: ('Connection aborted.', OSError("(104, 'ECONNRESET')"))
2020-04-14 17:00:58 ERROR (MainThread) [homeassistant.components.garmin_connect] Unknown error occurred during Garmin Connect get activity request
Traceback (most recent call last):
  File "/usr/local/lib/python3.7/site-packages/urllib3/connectionpool.py", line 672, in urlopen
    chunked=chunked,
  File "/usr/local/lib/python3.7/site-packages/urllib3/connectionpool.py", line 421, in _make_request
    six.raise_from(e, None)
  File "<string>", line 3, in raise_from
  File "/usr/local/lib/python3.7/site-packages/urllib3/connectionpool.py", line 416, in _make_request
    httplib_response = conn.getresponse()
  File "/usr/local/lib/python3.7/http/client.py", line 1344, in getresponse
    response.begin()
  File "/usr/local/lib/python3.7/http/client.py", line 306, in begin
    version, status, reason = self._read_status()
  File "/usr/local/lib/python3.7/http/client.py", line 267, in _read_status
    line = str(self.fp.readline(_MAXLINE + 1), "iso-8859-1")
  File "/usr/local/lib/python3.7/socket.py", line 589, in readinto
    return self._sock.recv_into(b)
  File "/usr/local/lib/python3.7/site-packages/urllib3/contrib/pyopenssl.py", line 318, in recv_into
    raise SocketError(str(e))
OSError: (104, 'ECONNRESET')

During handling of the above exception, another exception occurred:

Traceback (most recent call last):
  File "/usr/local/lib/python3.7/site-packages/requests/adapters.py", line 449, in send
    timeout=timeout
  File "/usr/local/lib/python3.7/site-packages/urllib3/connectionpool.py", line 720, in urlopen
    method, url, error=e, _pool=self, _stacktrace=sys.exc_info()[2]
  File "/usr/local/lib/python3.7/site-packages/urllib3/util/retry.py", line 400, in increment
    raise six.reraise(type(error), error, _stacktrace)
  File "/usr/local/lib/python3.7/site-packages/urllib3/packages/six.py", line 734, in reraise
    raise value.with_traceback(tb)
  File "/usr/local/lib/python3.7/site-packages/urllib3/connectionpool.py", line 672, in urlopen
    chunked=chunked,
  File "/usr/local/lib/python3.7/site-packages/urllib3/connectionpool.py", line 421, in _make_request
    six.raise_from(e, None)
  File "<string>", line 3, in raise_from
  File "/usr/local/lib/python3.7/site-packages/urllib3/connectionpool.py", line 416, in _make_request
    httplib_response = conn.getresponse()
  File "/usr/local/lib/python3.7/http/client.py", line 1344, in getresponse
    response.begin()
  File "/usr/local/lib/python3.7/http/client.py", line 306, in begin
    version, status, reason = self._read_status()
  File "/usr/local/lib/python3.7/http/client.py", line 267, in _read_status
    line = str(self.fp.readline(_MAXLINE + 1), "iso-8859-1")
  File "/usr/local/lib/python3.7/socket.py", line 589, in readinto
    return self._sock.recv_into(b)
  File "/usr/local/lib/python3.7/site-packages/urllib3/contrib/pyopenssl.py", line 318, in recv_into
    raise SocketError(str(e))
urllib3.exceptions.ProtocolError: ('Connection aborted.', OSError("(104, 'ECONNRESET')"))

During handling of the above exception, another exception occurred:

Traceback (most recent call last):
  File "/usr/src/homeassistant/homeassistant/components/garmin_connect/__init__.py", line 98, in async_update
    self.data = self.client.get_stats_and_body(today.isoformat())
  File "/usr/local/lib/python3.7/site-packages/garminconnect/__init__.py", line 146, in get_stats_and_body
    return ({**self.get_stats(cdate), **self.get_body_composition(cdate)})
  File "/usr/local/lib/python3.7/site-packages/garminconnect/__init__.py", line 155, in get_stats
    response = self.req.get(acturl, headers=self.headers)
  File "/usr/local/lib/python3.7/site-packages/requests/sessions.py", line 543, in get
    return self.request('GET', url, **kwargs)
  File "/usr/local/lib/python3.7/site-packages/requests/sessions.py", line 530, in request
    resp = self.send(prep, **send_kwargs)
  File "/usr/local/lib/python3.7/site-packages/requests/sessions.py", line 643, in send
    r = adapter.send(request, **kwargs)
  File "/usr/local/lib/python3.7/site-packages/requests/adapters.py", line 498, in send
    raise ConnectionError(err, request=request)
requests.exceptions.ConnectionError: ('Connection aborted.', OSError("(104, 'ECONNRESET')"))
2020-04-14 17:21:38 ERROR (MainThread) [homeassistant.components.garmin_connect] Unknown error occurred during Garmin Connect get activity request
Traceback (most recent call last):
  File "/usr/local/lib/python3.7/site-packages/urllib3/connectionpool.py", line 672, in urlopen
    chunked=chunked,
  File "/usr/local/lib/python3.7/site-packages/urllib3/connectionpool.py", line 421, in _make_request
    six.raise_from(e, None)
  File "<string>", line 3, in raise_from
  File "/usr/local/lib/python3.7/site-packages/urllib3/connectionpool.py", line 416, in _make_request
    httplib_response = conn.getresponse()
  File "/usr/local/lib/python3.7/http/client.py", line 1344, in getresponse
    response.begin()
  File "/usr/local/lib/python3.7/http/client.py", line 306, in begin
    version, status, reason = self._read_status()
  File "/usr/local/lib/python3.7/http/client.py", line 267, in _read_status
    line = str(self.fp.readline(_MAXLINE + 1), "iso-8859-1")
  File "/usr/local/lib/python3.7/socket.py", line 589, in readinto
    return self._sock.recv_into(b)
  File "/usr/local/lib/python3.7/site-packages/urllib3/contrib/pyopenssl.py", line 318, in recv_into
    raise SocketError(str(e))
OSError: (104, 'ECONNRESET')

During handling of the above exception, another exception occurred:

Traceback (most recent call last):
  File "/usr/local/lib/python3.7/site-packages/requests/adapters.py", line 449, in send
    timeout=timeout
  File "/usr/local/lib/python3.7/site-packages/urllib3/connectionpool.py", line 720, in urlopen
    method, url, error=e, _pool=self, _stacktrace=sys.exc_info()[2]
  File "/usr/local/lib/python3.7/site-packages/urllib3/util/retry.py", line 400, in increment
    raise six.reraise(type(error), error, _stacktrace)
  File "/usr/local/lib/python3.7/site-packages/urllib3/packages/six.py", line 734, in reraise
    raise value.with_traceback(tb)
  File "/usr/local/lib/python3.7/site-packages/urllib3/connectionpool.py", line 672, in urlopen
    chunked=chunked,
  File "/usr/local/lib/python3.7/site-packages/urllib3/connectionpool.py", line 421, in _make_request
    six.raise_from(e, None)
  File "<string>", line 3, in raise_from
  File "/usr/local/lib/python3.7/site-packages/urllib3/connectionpool.py", line 416, in _make_request
    httplib_response = conn.getresponse()
  File "/usr/local/lib/python3.7/http/client.py", line 1344, in getresponse
    response.begin()
  File "/usr/local/lib/python3.7/http/client.py", line 306, in begin
    version, status, reason = self._read_status()
  File "/usr/local/lib/python3.7/http/client.py", line 267, in _read_status
    line = str(self.fp.readline(_MAXLINE + 1), "iso-8859-1")
  File "/usr/local/lib/python3.7/socket.py", line 589, in readinto
    return self._sock.recv_into(b)
  File "/usr/local/lib/python3.7/site-packages/urllib3/contrib/pyopenssl.py", line 318, in recv_into
    raise SocketError(str(e))
urllib3.exceptions.ProtocolError: ('Connection aborted.', OSError("(104, 'ECONNRESET')"))

During handling of the above exception, another exception occurred:

Traceback (most recent call last):
  File "/usr/src/homeassistant/homeassistant/components/garmin_connect/__init__.py", line 98, in async_update
    self.data = self.client.get_stats_and_body(today.isoformat())
  File "/usr/local/lib/python3.7/site-packages/garminconnect/__init__.py", line 146, in get_stats_and_body
    return ({**self.get_stats(cdate), **self.get_body_composition(cdate)})
  File "/usr/local/lib/python3.7/site-packages/garminconnect/__init__.py", line 155, in get_stats
    response = self.req.get(acturl, headers=self.headers)
  File "/usr/local/lib/python3.7/site-packages/requests/sessions.py", line 543, in get
    return self.request('GET', url, **kwargs)
  File "/usr/local/lib/python3.7/site-packages/requests/sessions.py", line 530, in request
    resp = self.send(prep, **send_kwargs)
  File "/usr/local/lib/python3.7/site-packages/requests/sessions.py", line 643, in send
    r = adapter.send(request, **kwargs)
  File "/usr/local/lib/python3.7/site-packages/requests/adapters.py", line 498, in send
    raise ConnectionError(err, request=request)
requests.exceptions.ConnectionError: ('Connection aborted.', OSError("(104, 'ECONNRESET')"))
2020-04-14 17:42:18 ERROR (MainThread) [homeassistant.components.garmin_connect] Unknown error occurred during Garmin Connect get activity request
Traceback (most recent call last):
  File "/usr/local/lib/python3.7/site-packages/urllib3/connectionpool.py", line 672, in urlopen
    chunked=chunked,
  File "/usr/local/lib/python3.7/site-packages/urllib3/connectionpool.py", line 421, in _make_request
    six.raise_from(e, None)
  File "<string>", line 3, in raise_from
  File "/usr/local/lib/python3.7/site-packages/urllib3/connectionpool.py", line 416, in _make_request
    httplib_response = conn.getresponse()
  File "/usr/local/lib/python3.7/http/client.py", line 1344, in getresponse
    response.begin()
  File "/usr/local/lib/python3.7/http/client.py", line 306, in begin
    version, status, reason = self._read_status()
  File "/usr/local/lib/python3.7/http/client.py", line 267, in _read_status
    line = str(self.fp.readline(_MAXLINE + 1), "iso-8859-1")
  File "/usr/local/lib/python3.7/socket.py", line 589, in readinto
    return self._sock.recv_into(b)
  File "/usr/local/lib/python3.7/site-packages/urllib3/contrib/pyopenssl.py", line 318, in recv_into
    raise SocketError(str(e))
OSError: (104, 'ECONNRESET')

During handling of the above exception, another exception occurred:

Traceback (most recent call last):
  File "/usr/local/lib/python3.7/site-packages/requests/adapters.py", line 449, in send
    timeout=timeout
  File "/usr/local/lib/python3.7/site-packages/urllib3/connectionpool.py", line 720, in urlopen
    method, url, error=e, _pool=self, _stacktrace=sys.exc_info()[2]
  File "/usr/local/lib/python3.7/site-packages/urllib3/util/retry.py", line 400, in increment
    raise six.reraise(type(error), error, _stacktrace)
  File "/usr/local/lib/python3.7/site-packages/urllib3/packages/six.py", line 734, in reraise
    raise value.with_traceback(tb)
  File "/usr/local/lib/python3.7/site-packages/urllib3/connectionpool.py", line 672, in urlopen
    chunked=chunked,
  File "/usr/local/lib/python3.7/site-packages/urllib3/connectionpool.py", line 421, in _make_request
    six.raise_from(e, None)
  File "<string>", line 3, in raise_from
  File "/usr/local/lib/python3.7/site-packages/urllib3/connectionpool.py", line 416, in _make_request
    httplib_response = conn.getresponse()
  File "/usr/local/lib/python3.7/http/client.py", line 1344, in getresponse
    response.begin()
  File "/usr/local/lib/python3.7/http/client.py", line 306, in begin
    version, status, reason = self._read_status()
  File "/usr/local/lib/python3.7/http/client.py", line 267, in _read_status
    line = str(self.fp.readline(_MAXLINE + 1), "iso-8859-1")
  File "/usr/local/lib/python3.7/socket.py", line 589, in readinto
    return self._sock.recv_into(b)
  File "/usr/local/lib/python3.7/site-packages/urllib3/contrib/pyopenssl.py", line 318, in recv_into
    raise SocketError(str(e))
urllib3.exceptions.ProtocolError: ('Connection aborted.', OSError("(104, 'ECONNRESET')"))

During handling of the above exception, another exception occurred:

Traceback (most recent call last):
  File "/usr/src/homeassistant/homeassistant/components/garmin_connect/__init__.py", line 98, in async_update
    self.data = self.client.get_stats_and_body(today.isoformat())
  File "/usr/local/lib/python3.7/site-packages/garminconnect/__init__.py", line 146, in get_stats_and_body
    return ({**self.get_stats(cdate), **self.get_body_composition(cdate)})
  File "/usr/local/lib/python3.7/site-packages/garminconnect/__init__.py", line 155, in get_stats
    response = self.req.get(acturl, headers=self.headers)
  File "/usr/local/lib/python3.7/site-packages/requests/sessions.py", line 543, in get
    return self.request('GET', url, **kwargs)
  File "/usr/local/lib/python3.7/site-packages/requests/sessions.py", line 530, in request
    resp = self.send(prep, **send_kwargs)
  File "/usr/local/lib/python3.7/site-packages/requests/sessions.py", line 643, in send
    r = adapter.send(request, **kwargs)
  File "/usr/local/lib/python3.7/site-packages/requests/adapters.py", line 498, in send
    raise ConnectionError(err, request=request)
requests.exceptions.ConnectionError: ('Connection aborted.', OSError("(104, 'ECONNRESET')"))
2020-04-14 18:02:58 ERROR (MainThread) [homeassistant.components.garmin_connect] Unknown error occurred during Garmin Connect get activity request
Traceback (most recent call last):
  File "/usr/local/lib/python3.7/site-packages/urllib3/connectionpool.py", line 672, in urlopen
    chunked=chunked,
  File "/usr/local/lib/python3.7/site-packages/urllib3/connectionpool.py", line 421, in _make_request
    six.raise_from(e, None)
  File "<string>", line 3, in raise_from
  File "/usr/local/lib/python3.7/site-packages/urllib3/connectionpool.py", line 416, in _make_request
    httplib_response = conn.getresponse()
  File "/usr/local/lib/python3.7/http/client.py", line 1344, in getresponse
    response.begin()
  File "/usr/local/lib/python3.7/http/client.py", line 306, in begin
    version, status, reason = self._read_status()
  File "/usr/local/lib/python3.7/http/client.py", line 267, in _read_status
    line = str(self.fp.readline(_MAXLINE + 1), "iso-8859-1")
  File "/usr/local/lib/python3.7/socket.py", line 589, in readinto
    return self._sock.recv_into(b)
  File "/usr/local/lib/python3.7/site-packages/urllib3/contrib/pyopenssl.py", line 318, in recv_into
    raise SocketError(str(e))
OSError: (104, 'ECONNRESET')

During handling of the above exception, another exception occurred:

Traceback (most recent call last):
  File "/usr/local/lib/python3.7/site-packages/requests/adapters.py", line 449, in send
    timeout=timeout
  File "/usr/local/lib/python3.7/site-packages/urllib3/connectionpool.py", line 720, in urlopen
    method, url, error=e, _pool=self, _stacktrace=sys.exc_info()[2]
  File "/usr/local/lib/python3.7/site-packages/urllib3/util/retry.py", line 400, in increment
    raise six.reraise(type(error), error, _stacktrace)
  File "/usr/local/lib/python3.7/site-packages/urllib3/packages/six.py", line 734, in reraise
    raise value.with_traceback(tb)
  File "/usr/local/lib/python3.7/site-packages/urllib3/connectionpool.py", line 672, in urlopen
    chunked=chunked,
  File "/usr/local/lib/python3.7/site-packages/urllib3/connectionpool.py", line 421, in _make_request
    six.raise_from(e, None)
  File "<string>", line 3, in raise_from
  File "/usr/local/lib/python3.7/site-packages/urllib3/connectionpool.py", line 416, in _make_request
    httplib_response = conn.getresponse()
  File "/usr/local/lib/python3.7/http/client.py", line 1344, in getresponse
    response.begin()
  File "/usr/local/lib/python3.7/http/client.py", line 306, in begin
    version, status, reason = self._read_status()
  File "/usr/local/lib/python3.7/http/client.py", line 267, in _read_status
    line = str(self.fp.readline(_MAXLINE + 1), "iso-8859-1")
  File "/usr/local/lib/python3.7/socket.py", line 589, in readinto
    return self._sock.recv_into(b)
  File "/usr/local/lib/python3.7/site-packages/urllib3/contrib/pyopenssl.py", line 318, in recv_into
    raise SocketError(str(e))
urllib3.exceptions.ProtocolError: ('Connection aborted.', OSError("(104, 'ECONNRESET')"))

During handling of the above exception, another exception occurred:

Traceback (most recent call last):
  File "/usr/src/homeassistant/homeassistant/components/garmin_connect/__init__.py", line 98, in async_update
    self.data = self.client.get_stats_and_body(today.isoformat())
  File "/usr/local/lib/python3.7/site-packages/garminconnect/__init__.py", line 146, in get_stats_and_body
    return ({**self.get_stats(cdate), **self.get_body_composition(cdate)})
  File "/usr/local/lib/python3.7/site-packages/garminconnect/__init__.py", line 155, in get_stats
    response = self.req.get(acturl, headers=self.headers)
  File "/usr/local/lib/python3.7/site-packages/requests/sessions.py", line 543, in get
    return self.request('GET', url, **kwargs)
  File "/usr/local/lib/python3.7/site-packages/requests/sessions.py", line 530, in request
    resp = self.send(prep, **send_kwargs)
  File "/usr/local/lib/python3.7/site-packages/requests/sessions.py", line 643, in send
    r = adapter.send(request, **kwargs)
  File "/usr/local/lib/python3.7/site-packages/requests/adapters.py", line 498, in send
    raise ConnectionError(err, request=request)
requests.exceptions.ConnectionError: ('Connection aborted.', OSError("(104, 'ECONNRESET')"))
2020-04-14 18:23:38 ERROR (MainThread) [homeassistant.components.garmin_connect] Unknown error occurred during Garmin Connect get activity request
Traceback (most recent call last):
  File "/usr/local/lib/python3.7/site-packages/urllib3/connectionpool.py", line 672, in urlopen
    chunked=chunked,
  File "/usr/local/lib/python3.7/site-packages/urllib3/connectionpool.py", line 421, in _make_request
    six.raise_from(e, None)
  File "<string>", line 3, in raise_from
  File "/usr/local/lib/python3.7/site-packages/urllib3/connectionpool.py", line 416, in _make_request
    httplib_response = conn.getresponse()
  File "/usr/local/lib/python3.7/http/client.py", line 1344, in getresponse
    response.begin()
  File "/usr/local/lib/python3.7/http/client.py", line 306, in begin
    version, status, reason = self._read_status()
  File "/usr/local/lib/python3.7/http/client.py", line 267, in _read_status
    line = str(self.fp.readline(_MAXLINE + 1), "iso-8859-1")
  File "/usr/local/lib/python3.7/socket.py", line 589, in readinto
    return self._sock.recv_into(b)
  File "/usr/local/lib/python3.7/site-packages/urllib3/contrib/pyopenssl.py", line 318, in recv_into
    raise SocketError(str(e))
OSError: (104, 'ECONNRESET')

During handling of the above exception, another exception occurred:

Traceback (most recent call last):
  File "/usr/local/lib/python3.7/site-packages/requests/adapters.py", line 449, in send
    timeout=timeout
  File "/usr/local/lib/python3.7/site-packages/urllib3/connectionpool.py", line 720, in urlopen
    method, url, error=e, _pool=self, _stacktrace=sys.exc_info()[2]
  File "/usr/local/lib/python3.7/site-packages/urllib3/util/retry.py", line 400, in increment
    raise six.reraise(type(error), error, _stacktrace)
  File "/usr/local/lib/python3.7/site-packages/urllib3/packages/six.py", line 734, in reraise
    raise value.with_traceback(tb)
  File "/usr/local/lib/python3.7/site-packages/urllib3/connectionpool.py", line 672, in urlopen
    chunked=chunked,
  File "/usr/local/lib/python3.7/site-packages/urllib3/connectionpool.py", line 421, in _make_request
    six.raise_from(e, None)
  File "<string>", line 3, in raise_from
  File "/usr/local/lib/python3.7/site-packages/urllib3/connectionpool.py", line 416, in _make_request
    httplib_response = conn.getresponse()
  File "/usr/local/lib/python3.7/http/client.py", line 1344, in getresponse
    response.begin()
  File "/usr/local/lib/python3.7/http/client.py", line 306, in begin
    version, status, reason = self._read_status()
  File "/usr/local/lib/python3.7/http/client.py", line 267, in _read_status
    line = str(self.fp.readline(_MAXLINE + 1), "iso-8859-1")
  File "/usr/local/lib/python3.7/socket.py", line 589, in readinto
    return self._sock.recv_into(b)
  File "/usr/local/lib/python3.7/site-packages/urllib3/contrib/pyopenssl.py", line 318, in recv_into
    raise SocketError(str(e))
urllib3.exceptions.ProtocolError: ('Connection aborted.', OSError("(104, 'ECONNRESET')"))

During handling of the above exception, another exception occurred:

Traceback (most recent call last):
  File "/usr/src/homeassistant/homeassistant/components/garmin_connect/__init__.py", line 98, in async_update
    self.data = self.client.get_stats_and_body(today.isoformat())
  File "/usr/local/lib/python3.7/site-packages/garminconnect/__init__.py", line 146, in get_stats_and_body
    return ({**self.get_stats(cdate), **self.get_body_composition(cdate)})
  File "/usr/local/lib/python3.7/site-packages/garminconnect/__init__.py", line 155, in get_stats
    response = self.req.get(acturl, headers=self.headers)
  File "/usr/local/lib/python3.7/site-packages/requests/sessions.py", line 543, in get
    return self.request('GET', url, **kwargs)
  File "/usr/local/lib/python3.7/site-packages/requests/sessions.py", line 530, in request
    resp = self.send(prep, **send_kwargs)
  File "/usr/local/lib/python3.7/site-packages/requests/sessions.py", line 643, in send
    r = adapter.send(request, **kwargs)
  File "/usr/local/lib/python3.7/site-packages/requests/adapters.py", line 498, in send
    raise ConnectionError(err, request=request)
requests.exceptions.ConnectionError: ('Connection aborted.', OSError("(104, 'ECONNRESET')"))
2020-04-14 18:39:32 ERROR (MainThread) [homeassistant.components.websocket_api.http.connection.1847711984] payload must be a string, bytearray, int, float or None.
Traceback (most recent call last):
  File "/usr/src/homeassistant/homeassistant/components/websocket_api/commands.py", line 134, in handle_call_service
    connection.context(msg),
  File "/usr/src/homeassistant/homeassistant/core.py", line 1232, in async_call
    await asyncio.shield(self._execute_service(handler, service_call))
  File "/usr/src/homeassistant/homeassistant/core.py", line 1255, in _execute_service
    await handler.func(service_call)
  File "/usr/src/homeassistant/homeassistant/components/mqtt/__init__.py", line 687, in async_publish_service
    await hass.data[DATA_MQTT].async_publish(msg_topic, payload, qos, retain)
  File "/usr/src/homeassistant/homeassistant/components/mqtt/__init__.py", line 825, in async_publish
    self._mqttc.publish, topic, payload, qos, retain
  File "/usr/local/lib/python3.7/concurrent/futures/thread.py", line 57, in run
    result = self.fn(*self.args, **self.kwargs)
  File "/usr/local/lib/python3.7/site-packages/paho/mqtt/client.py", line 1260, in publish
    'payload must be a string, bytearray, int, float or None.')
TypeError: payload must be a string, bytearray, int, float or None.
2020-04-14 18:39:35 ERROR (MainThread) [homeassistant.components.websocket_api.http.connection.1847711984] payload must be a string, bytearray, int, float or None.
Traceback (most recent call last):
  File "/usr/src/homeassistant/homeassistant/components/websocket_api/commands.py", line 134, in handle_call_service
    connection.context(msg),
  File "/usr/src/homeassistant/homeassistant/core.py", line 1232, in async_call
    await asyncio.shield(self._execute_service(handler, service_call))
  File "/usr/src/homeassistant/homeassistant/core.py", line 1255, in _execute_service
    await handler.func(service_call)
  File "/usr/src/homeassistant/homeassistant/components/mqtt/__init__.py", line 687, in async_publish_service
    await hass.data[DATA_MQTT].async_publish(msg_topic, payload, qos, retain)
  File "/usr/src/homeassistant/homeassistant/components/mqtt/__init__.py", line 825, in async_publish
    self._mqttc.publish, topic, payload, qos, retain
  File "/usr/local/lib/python3.7/concurrent/futures/thread.py", line 57, in run
    result = self.fn(*self.args, **self.kwargs)
  File "/usr/local/lib/python3.7/site-packages/paho/mqtt/client.py", line 1260, in publish
    'payload must be a string, bytearray, int, float or None.')
TypeError: payload must be a string, bytearray, int, float or None.
2020-04-14 18:39:36 ERROR (MainThread) [homeassistant.components.websocket_api.http.connection.1847711984] payload must be a string, bytearray, int, float or None.
Traceback (most recent call last):
  File "/usr/src/homeassistant/homeassistant/components/websocket_api/commands.py", line 134, in handle_call_service
    connection.context(msg),
  File "/usr/src/homeassistant/homeassistant/core.py", line 1232, in async_call
    await asyncio.shield(self._execute_service(handler, service_call))
  File "/usr/src/homeassistant/homeassistant/core.py", line 1255, in _execute_service
    await handler.func(service_call)
  File "/usr/src/homeassistant/homeassistant/components/mqtt/__init__.py", line 687, in async_publish_service
    await hass.data[DATA_MQTT].async_publish(msg_topic, payload, qos, retain)
  File "/usr/src/homeassistant/homeassistant/components/mqtt/__init__.py", line 825, in async_publish
    self._mqttc.publish, topic, payload, qos, retain
  File "/usr/local/lib/python3.7/concurrent/futures/thread.py", line 57, in run
    result = self.fn(*self.args, **self.kwargs)
  File "/usr/local/lib/python3.7/site-packages/paho/mqtt/client.py", line 1260, in publish
    'payload must be a string, bytearray, int, float or None.')
TypeError: payload must be a string, bytearray, int, float or None.
2020-04-14 18:39:37 ERROR (MainThread) [homeassistant.components.websocket_api.http.connection.1847711984] payload must be a string, bytearray, int, float or None.
Traceback (most recent call last):
  File "/usr/src/homeassistant/homeassistant/components/websocket_api/commands.py", line 134, in handle_call_service
    connection.context(msg),
  File "/usr/src/homeassistant/homeassistant/core.py", line 1232, in async_call
    await asyncio.shield(self._execute_service(handler, service_call))
  File "/usr/src/homeassistant/homeassistant/core.py", line 1255, in _execute_service
    await handler.func(service_call)
  File "/usr/src/homeassistant/homeassistant/components/mqtt/__init__.py", line 687, in async_publish_service
    await hass.data[DATA_MQTT].async_publish(msg_topic, payload, qos, retain)
  File "/usr/src/homeassistant/homeassistant/components/mqtt/__init__.py", line 825, in async_publish
    self._mqttc.publish, topic, payload, qos, retain
  File "/usr/local/lib/python3.7/concurrent/futures/thread.py", line 57, in run
    result = self.fn(*self.args, **self.kwargs)
  File "/usr/local/lib/python3.7/site-packages/paho/mqtt/client.py", line 1260, in publish
    'payload must be a string, bytearray, int, float or None.')
TypeError: payload must be a string, bytearray, int, float or None.
2020-04-14 18:40:35 ERROR (MainThread) [homeassistant.components.websocket_api.http.connection.1847711984] payload must be a string, bytearray, int, float or None.
Traceback (most recent call last):
  File "/usr/src/homeassistant/homeassistant/components/websocket_api/commands.py", line 134, in handle_call_service
    connection.context(msg),
  File "/usr/src/homeassistant/homeassistant/core.py", line 1232, in async_call
    await asyncio.shield(self._execute_service(handler, service_call))
  File "/usr/src/homeassistant/homeassistant/core.py", line 1255, in _execute_service
    await handler.func(service_call)
  File "/usr/src/homeassistant/homeassistant/components/mqtt/__init__.py", line 687, in async_publish_service
    await hass.data[DATA_MQTT].async_publish(msg_topic, payload, qos, retain)
  File "/usr/src/homeassistant/homeassistant/components/mqtt/__init__.py", line 825, in async_publish
    self._mqttc.publish, topic, payload, qos, retain
  File "/usr/local/lib/python3.7/concurrent/futures/thread.py", line 57, in run
    result = self.fn(*self.args, **self.kwargs)
  File "/usr/local/lib/python3.7/site-packages/paho/mqtt/client.py", line 1260, in publish
    'payload must be a string, bytearray, int, float or None.')
TypeError: payload must be a string, bytearray, int, float or None.
2020-04-14 18:40:37 ERROR (MainThread) [homeassistant.components.websocket_api.http.connection.1847711984] payload must be a string, bytearray, int, float or None.
Traceback (most recent call last):
  File "/usr/src/homeassistant/homeassistant/components/websocket_api/commands.py", line 134, in handle_call_service
    connection.context(msg),
  File "/usr/src/homeassistant/homeassistant/core.py", line 1232, in async_call
    await asyncio.shield(self._execute_service(handler, service_call))
  File "/usr/src/homeassistant/homeassistant/core.py", line 1255, in _execute_service
    await handler.func(service_call)
  File "/usr/src/homeassistant/homeassistant/components/mqtt/__init__.py", line 687, in async_publish_service
    await hass.data[DATA_MQTT].async_publish(msg_topic, payload, qos, retain)
  File "/usr/src/homeassistant/homeassistant/components/mqtt/__init__.py", line 825, in async_publish
    self._mqttc.publish, topic, payload, qos, retain
  File "/usr/local/lib/python3.7/concurrent/futures/thread.py", line 57, in run
    result = self.fn(*self.args, **self.kwargs)
  File "/usr/local/lib/python3.7/site-packages/paho/mqtt/client.py", line 1260, in publish
    'payload must be a string, bytearray, int, float or None.')
TypeError: payload must be a string, bytearray, int, float or None.
2020-04-14 18:40:48 ERROR (MainThread) [homeassistant.components.websocket_api.http.connection.1847711984] payload must be a string, bytearray, int, float or None.
Traceback (most recent call last):
  File "/usr/src/homeassistant/homeassistant/components/websocket_api/commands.py", line 134, in handle_call_service
    connection.context(msg),
  File "/usr/src/homeassistant/homeassistant/core.py", line 1232, in async_call
    await asyncio.shield(self._execute_service(handler, service_call))
  File "/usr/src/homeassistant/homeassistant/core.py", line 1255, in _execute_service
    await handler.func(service_call)
  File "/usr/src/homeassistant/homeassistant/components/mqtt/__init__.py", line 687, in async_publish_service
    await hass.data[DATA_MQTT].async_publish(msg_topic, payload, qos, retain)
  File "/usr/src/homeassistant/homeassistant/components/mqtt/__init__.py", line 825, in async_publish
    self._mqttc.publish, topic, payload, qos, retain
  File "/usr/local/lib/python3.7/concurrent/futures/thread.py", line 57, in run
    result = self.fn(*self.args, **self.kwargs)
  File "/usr/local/lib/python3.7/site-packages/paho/mqtt/client.py", line 1260, in publish
    'payload must be a string, bytearray, int, float or None.')
TypeError: payload must be a string, bytearray, int, float or None.
2020-04-14 18:40:52 ERROR (MainThread) [homeassistant.components.websocket_api.http.connection.1847711984] payload must be a string, bytearray, int, float or None.
Traceback (most recent call last):
  File "/usr/src/homeassistant/homeassistant/components/websocket_api/commands.py", line 134, in handle_call_service
    connection.context(msg),
  File "/usr/src/homeassistant/homeassistant/core.py", line 1232, in async_call
    await asyncio.shield(self._execute_service(handler, service_call))
  File "/usr/src/homeassistant/homeassistant/core.py", line 1255, in _execute_service
    await handler.func(service_call)
  File "/usr/src/homeassistant/homeassistant/components/mqtt/__init__.py", line 687, in async_publish_service
    await hass.data[DATA_MQTT].async_publish(msg_topic, payload, qos, retain)
  File "/usr/src/homeassistant/homeassistant/components/mqtt/__init__.py", line 825, in async_publish
    self._mqttc.publish, topic, payload, qos, retain
  File "/usr/local/lib/python3.7/concurrent/futures/thread.py", line 57, in run
    result = self.fn(*self.args, **self.kwargs)
  File "/usr/local/lib/python3.7/site-packages/paho/mqtt/client.py", line 1260, in publish
    'payload must be a string, bytearray, int, float or None.')
TypeError: payload must be a string, bytearray, int, float or None.
2020-04-14 18:44:18 ERROR (MainThread) [homeassistant.components.garmin_connect] Unknown error occurred during Garmin Connect get activity request
Traceback (most recent call last):
  File "/usr/local/lib/python3.7/site-packages/urllib3/connectionpool.py", line 672, in urlopen
    chunked=chunked,
  File "/usr/local/lib/python3.7/site-packages/urllib3/connectionpool.py", line 421, in _make_request
    six.raise_from(e, None)
  File "<string>", line 3, in raise_from
  File "/usr/local/lib/python3.7/site-packages/urllib3/connectionpool.py", line 416, in _make_request
    httplib_response = conn.getresponse()
  File "/usr/local/lib/python3.7/http/client.py", line 1344, in getresponse
    response.begin()
  File "/usr/local/lib/python3.7/http/client.py", line 306, in begin
    version, status, reason = self._read_status()
  File "/usr/local/lib/python3.7/http/client.py", line 267, in _read_status
    line = str(self.fp.readline(_MAXLINE + 1), "iso-8859-1")
  File "/usr/local/lib/python3.7/socket.py", line 589, in readinto
    return self._sock.recv_into(b)
  File "/usr/local/lib/python3.7/site-packages/urllib3/contrib/pyopenssl.py", line 318, in recv_into
    raise SocketError(str(e))
OSError: (104, 'ECONNRESET')

During handling of the above exception, another exception occurred:

Traceback (most recent call last):
  File "/usr/local/lib/python3.7/site-packages/requests/adapters.py", line 449, in send
    timeout=timeout
  File "/usr/local/lib/python3.7/site-packages/urllib3/connectionpool.py", line 720, in urlopen
    method, url, error=e, _pool=self, _stacktrace=sys.exc_info()[2]
  File "/usr/local/lib/python3.7/site-packages/urllib3/util/retry.py", line 400, in increment
    raise six.reraise(type(error), error, _stacktrace)
  File "/usr/local/lib/python3.7/site-packages/urllib3/packages/six.py", line 734, in reraise
    raise value.with_traceback(tb)
  File "/usr/local/lib/python3.7/site-packages/urllib3/connectionpool.py", line 672, in urlopen
    chunked=chunked,
  File "/usr/local/lib/python3.7/site-packages/urllib3/connectionpool.py", line 421, in _make_request
    six.raise_from(e, None)
  File "<string>", line 3, in raise_from
  File "/usr/local/lib/python3.7/site-packages/urllib3/connectionpool.py", line 416, in _make_request
    httplib_response = conn.getresponse()
  File "/usr/local/lib/python3.7/http/client.py", line 1344, in getresponse
    response.begin()
  File "/usr/local/lib/python3.7/http/client.py", line 306, in begin
    version, status, reason = self._read_status()
  File "/usr/local/lib/python3.7/http/client.py", line 267, in _read_status
    line = str(self.fp.readline(_MAXLINE + 1), "iso-8859-1")
  File "/usr/local/lib/python3.7/socket.py", line 589, in readinto
    return self._sock.recv_into(b)
  File "/usr/local/lib/python3.7/site-packages/urllib3/contrib/pyopenssl.py", line 318, in recv_into
    raise SocketError(str(e))
urllib3.exceptions.ProtocolError: ('Connection aborted.', OSError("(104, 'ECONNRESET')"))

During handling of the above exception, another exception occurred:

Traceback (most recent call last):
  File "/usr/src/homeassistant/homeassistant/components/garmin_connect/__init__.py", line 98, in async_update
    self.data = self.client.get_stats_and_body(today.isoformat())
  File "/usr/local/lib/python3.7/site-packages/garminconnect/__init__.py", line 146, in get_stats_and_body
    return ({**self.get_stats(cdate), **self.get_body_composition(cdate)})
  File "/usr/local/lib/python3.7/site-packages/garminconnect/__init__.py", line 155, in get_stats
    response = self.req.get(acturl, headers=self.headers)
  File "/usr/local/lib/python3.7/site-packages/requests/sessions.py", line 543, in get
    return self.request('GET', url, **kwargs)
  File "/usr/local/lib/python3.7/site-packages/requests/sessions.py", line 530, in request
    resp = self.send(prep, **send_kwargs)
  File "/usr/local/lib/python3.7/site-packages/requests/sessions.py", line 643, in send
    r = adapter.send(request, **kwargs)
  File "/usr/local/lib/python3.7/site-packages/requests/adapters.py", line 498, in send
    raise ConnectionError(err, request=request)
requests.exceptions.ConnectionError: ('Connection aborted.', OSError("(104, 'ECONNRESET')"))
