2020-05-17 19:13:52 WARNING (MainThread) [homeassistant.loader] You are using a custom integration for mohan_helloworld which has not been tested by Home Assistant. This component might cause stability problems, be sure to disable it if you experience issues with Home Assistant.
2020-05-17 19:13:57 WARNING (MainThread) [homeassistant.loader] You are using a custom integration for hacs which has not been tested by Home Assistant. This component might cause stability problems, be sure to disable it if you experience issues with Home Assistant.
2020-05-17 19:13:59 WARNING (Recorder) [homeassistant.components.recorder] Ended unfinished session (id=216 from 2020-05-17 08:58:22.322731)
2020-05-17 19:14:10 WARNING (MainThread) [homeassistant.loader] You are using a custom integration for bom_forecast which has not been tested by Home Assistant. This component might cause stability problems, be sure to disable it if you experience issues with Home Assistant.
2020-05-17 19:14:14 WARNING (MainThread) [homeassistant.loader] You are using a custom integration for mohan_sensor which has not been tested by Home Assistant. This component might cause stability problems, be sure to disable it if you experience issues with Home Assistant.
2020-05-17 19:14:22 WARNING (MainThread) [homeassistant.components.mobile_app.notify] Found duplicate device name Aruna Gupta’s iPhone
2020-05-17 19:14:22 WARNING (MainThread) [homeassistant.components.mobile_app.notify] Found duplicate device name Aruna Gupta’s iPhone
2020-05-17 19:14:22 WARNING (MainThread) [homeassistant.components.mobile_app.notify] Found duplicate device name Aruna Gupta’s iPhone
2020-05-17 19:14:22 WARNING (MainThread) [homeassistant.components.mobile_app.notify] Found duplicate device name Aruna Gupta’s iPhone
2020-05-17 19:14:25 WARNING (MainThread) [homeassistant.components.weather] Setup of weather platform met is taking over 10 seconds.
2020-05-17 19:14:39 WARNING (MainThread) [homeassistant.helpers.translation] hacs: the '.translations' directory has been moved, the new name is 'translations', starting with Home Assistant 0.111 your translations will no longer load if you do not move/rename this 
2020-05-17 19:14:42 WARNING (MainThread) [homeassistant.helpers.translation] hacs: the '.translations' directory has been moved, the new name is 'translations', starting with Home Assistant 0.111 your translations will no longer load if you do not move/rename this 
2020-05-17 19:14:54 WARNING (MainThread) [homeassistant.helpers.translation] hacs: the '.translations' directory has been moved, the new name is 'translations', starting with Home Assistant 0.111 your translations will no longer load if you do not move/rename this 
2020-05-17 19:15:32 ERROR (Recorder) [homeassistant.components.recorder] Error adding event: (sqlite3.OperationalError) database is locked
(Background on this error at: http://sqlalche.me/e/e3q8)
Traceback (most recent call last):
  File "/usr/local/lib/python3.7/site-packages/sqlalchemy/engine/base.py", line 2285, in _wrap_pool_connect
    return fn()
  File "/usr/local/lib/python3.7/site-packages/sqlalchemy/pool/base.py", line 363, in connect
    return _ConnectionFairy._checkout(self)
  File "/usr/local/lib/python3.7/site-packages/sqlalchemy/pool/base.py", line 773, in _checkout
    fairy = _ConnectionRecord.checkout(pool)
  File "/usr/local/lib/python3.7/site-packages/sqlalchemy/pool/base.py", line 492, in checkout
    rec = pool._do_get()
  File "/usr/local/lib/python3.7/site-packages/sqlalchemy/pool/impl.py", line 238, in _do_get
    return self._create_connection()
  File "/usr/local/lib/python3.7/site-packages/sqlalchemy/pool/base.py", line 308, in _create_connection
    return _ConnectionRecord(self)
  File "/usr/local/lib/python3.7/site-packages/sqlalchemy/pool/base.py", line 437, in __init__
    self.__connect(first_connect_check=True)
  File "/usr/local/lib/python3.7/site-packages/sqlalchemy/pool/base.py", line 664, in __connect
    pool.dispatch.connect(self.connection, self)
  File "/usr/local/lib/python3.7/site-packages/sqlalchemy/event/attr.py", line 322, in __call__
    fn(*args, **kw)
  File "/usr/src/homeassistant/homeassistant/components/recorder/__init__.py", line 499, in setup_recorder_connection
    cursor.execute("PRAGMA journal_mode=WAL")
sqlite3.OperationalError: database is locked

The above exception was the direct cause of the following exception:

Traceback (most recent call last):
  File "/usr/src/homeassistant/homeassistant/components/recorder/__init__.py", line 372, in run
    self.event_session.flush()
  File "/usr/local/lib/python3.7/site-packages/sqlalchemy/orm/session.py", line 2496, in flush
    self._flush(objects)
  File "/usr/local/lib/python3.7/site-packages/sqlalchemy/orm/session.py", line 2637, in _flush
    transaction.rollback(_capture_exception=True)
  File "/usr/local/lib/python3.7/site-packages/sqlalchemy/util/langhelpers.py", line 69, in __exit__
    exc_value, with_traceback=exc_tb,
  File "/usr/local/lib/python3.7/site-packages/sqlalchemy/util/compat.py", line 178, in raise_
    raise exception
  File "/usr/local/lib/python3.7/site-packages/sqlalchemy/orm/session.py", line 2597, in _flush
    flush_context.execute()
  File "/usr/local/lib/python3.7/site-packages/sqlalchemy/orm/unitofwork.py", line 422, in execute
    rec.execute(self)
  File "/usr/local/lib/python3.7/site-packages/sqlalchemy/orm/unitofwork.py", line 589, in execute
    uow,
  File "/usr/local/lib/python3.7/site-packages/sqlalchemy/orm/persistence.py", line 213, in save_obj
    ) in _organize_states_for_save(base_mapper, states, uowtransaction):
  File "/usr/local/lib/python3.7/site-packages/sqlalchemy/orm/persistence.py", line 374, in _organize_states_for_save
    base_mapper, uowtransaction, states
  File "/usr/local/lib/python3.7/site-packages/sqlalchemy/orm/persistence.py", line 1602, in _connections_for_states
    connection = uowtransaction.transaction.connection(base_mapper)
  File "/usr/local/lib/python3.7/site-packages/sqlalchemy/orm/session.py", line 313, in connection
    return self._connection_for_bind(bind, execution_options)
  File "/usr/local/lib/python3.7/site-packages/sqlalchemy/orm/session.py", line 420, in _connection_for_bind
    conn = self._parent._connection_for_bind(bind, execution_options)
  File "/usr/local/lib/python3.7/site-packages/sqlalchemy/orm/session.py", line 432, in _connection_for_bind
    conn = bind._contextual_connect()
  File "/usr/local/lib/python3.7/site-packages/sqlalchemy/engine/base.py", line 2251, in _contextual_connect
    self._wrap_pool_connect(self.pool.connect, None),
  File "/usr/local/lib/python3.7/site-packages/sqlalchemy/engine/base.py", line 2289, in _wrap_pool_connect
    e, dialect, self
  File "/usr/local/lib/python3.7/site-packages/sqlalchemy/engine/base.py", line 1555, in _handle_dbapi_exception_noconnection
    sqlalchemy_exception, with_traceback=exc_info[2], from_=e
  File "/usr/local/lib/python3.7/site-packages/sqlalchemy/util/compat.py", line 178, in raise_
    raise exception
  File "/usr/local/lib/python3.7/site-packages/sqlalchemy/engine/base.py", line 2285, in _wrap_pool_connect
    return fn()
  File "/usr/local/lib/python3.7/site-packages/sqlalchemy/pool/base.py", line 363, in connect
    return _ConnectionFairy._checkout(self)
  File "/usr/local/lib/python3.7/site-packages/sqlalchemy/pool/base.py", line 773, in _checkout
    fairy = _ConnectionRecord.checkout(pool)
  File "/usr/local/lib/python3.7/site-packages/sqlalchemy/pool/base.py", line 492, in checkout
    rec = pool._do_get()
  File "/usr/local/lib/python3.7/site-packages/sqlalchemy/pool/impl.py", line 238, in _do_get
    return self._create_connection()
  File "/usr/local/lib/python3.7/site-packages/sqlalchemy/pool/base.py", line 308, in _create_connection
    return _ConnectionRecord(self)
  File "/usr/local/lib/python3.7/site-packages/sqlalchemy/pool/base.py", line 437, in __init__
    self.__connect(first_connect_check=True)
  File "/usr/local/lib/python3.7/site-packages/sqlalchemy/pool/base.py", line 664, in __connect
    pool.dispatch.connect(self.connection, self)
  File "/usr/local/lib/python3.7/site-packages/sqlalchemy/event/attr.py", line 322, in __call__
    fn(*args, **kw)
  File "/usr/src/homeassistant/homeassistant/components/recorder/__init__.py", line 499, in setup_recorder_connection
    cursor.execute("PRAGMA journal_mode=WAL")
sqlalchemy.exc.OperationalError: (sqlite3.OperationalError) database is locked
(Background on this error at: http://sqlalche.me/e/e3q8)
2020-05-17 19:15:39 ERROR (Recorder) [homeassistant.components.recorder] Error executing query: This Session's transaction has been rolled back due to a previous exception during flush. To begin a new transaction with this Session, first issue Session.rollback(). Original exception was: (sqlite3.OperationalError) database is locked
(Background on this error at: http://sqlalche.me/e/e3q8) (Background on this error at: http://sqlalche.me/e/7s2a)
2020-05-17 19:15:41 ERROR (Recorder) [homeassistant.components.recorder] Error saving events: This Session's transaction has been rolled back due to a previous exception during flush. To begin a new transaction with this Session, first issue Session.rollback(). Original exception was: (sqlite3.OperationalError) database is locked
(Background on this error at: http://sqlalche.me/e/e3q8) (Background on this error at: http://sqlalche.me/e/7s2a)
Traceback (most recent call last):
  File "/usr/src/homeassistant/homeassistant/components/recorder/__init__.py", line 419, in _commit_event_session_or_retry
    self._commit_event_session()
  File "/usr/src/homeassistant/homeassistant/components/recorder/__init__.py", line 470, in _commit_event_session
    self.event_session.commit()
  File "/usr/local/lib/python3.7/site-packages/sqlalchemy/orm/session.py", line 1036, in commit
    self.transaction.commit()
  File "/usr/local/lib/python3.7/site-packages/sqlalchemy/orm/session.py", line 501, in commit
    self._assert_active(prepared_ok=True)
  File "/usr/local/lib/python3.7/site-packages/sqlalchemy/orm/session.py", line 295, in _assert_active
    code="7s2a",
sqlalchemy.exc.InvalidRequestError: This Session's transaction has been rolled back due to a previous exception during flush. To begin a new transaction with this Session, first issue Session.rollback(). Original exception was: (sqlite3.OperationalError) database is locked
(Background on this error at: http://sqlalche.me/e/e3q8) (Background on this error at: http://sqlalche.me/e/7s2a)
2020-05-17 19:23:17 WARNING (MainThread) [homeassistant.helpers.service] Unable to find referenced entities sensor.relative_sensor
2020-05-17 19:23:24 WARNING (MainThread) [homeassistant.helpers.service] Unable to find referenced entities sensor.relative_sensor
2020-05-17 20:14:27 ERROR (SyncWorker_0) [homeassistant.components.rest.sensor] Error fetching data: http://www.bom.gov.au/vic/forecasts/melbourne.shtml failed with ('Connection aborted.', ConnectionResetError(104, 'Connection reset by peer'))
2020-05-17 20:14:27 ERROR (SyncWorker_0) [homeassistant.components.scrape.sensor] Unable to retrieve data
2020-05-17 22:14:29 ERROR (SyncWorker_4) [homeassistant.components.rest.sensor] Error fetching data: http://www.bom.gov.au/vic/forecasts/melbourne.shtml failed with ('Connection aborted.', ConnectionResetError(104, 'Connection reset by peer'))
2020-05-17 22:14:29 ERROR (SyncWorker_4) [homeassistant.components.scrape.sensor] Unable to retrieve data
2020-05-18 00:14:31 ERROR (SyncWorker_17) [homeassistant.components.rest.sensor] Error fetching data: http://www.bom.gov.au/vic/forecasts/melbourne.shtml failed with ('Connection aborted.', ConnectionResetError(104, 'Connection reset by peer'))
2020-05-18 00:14:31 ERROR (SyncWorker_17) [homeassistant.components.scrape.sensor] Unable to retrieve data
2020-05-18 02:14:33 ERROR (SyncWorker_6) [homeassistant.components.rest.sensor] Error fetching data: http://www.bom.gov.au/vic/forecasts/melbourne.shtml failed with ('Connection aborted.', ConnectionResetError(104, 'Connection reset by peer'))
2020-05-18 02:14:33 ERROR (SyncWorker_6) [homeassistant.components.scrape.sensor] Unable to retrieve data
2020-05-18 04:14:35 ERROR (SyncWorker_11) [homeassistant.components.rest.sensor] Error fetching data: http://www.bom.gov.au/vic/forecasts/melbourne.shtml failed with ('Connection aborted.', ConnectionResetError(104, 'Connection reset by peer'))
2020-05-18 04:14:35 ERROR (SyncWorker_11) [homeassistant.components.scrape.sensor] Unable to retrieve data
2020-05-18 04:32:42 WARNING (Thread-3) [pychromecast.socket_client] [Rumpus room Speaker(192.168.20.10):8009] Heartbeat timeout, resetting connection
2020-05-18 04:33:03 WARNING (Thread-3) [pychromecast.socket_client] [Rumpus room Speaker(192.168.20.10):8009] Connection reestablished!
2020-05-18 06:14:37 ERROR (SyncWorker_19) [homeassistant.components.rest.sensor] Error fetching data: http://www.bom.gov.au/vic/forecasts/melbourne.shtml failed with ('Connection aborted.', ConnectionResetError(104, 'Connection reset by peer'))
2020-05-18 06:14:37 ERROR (SyncWorker_19) [homeassistant.components.scrape.sensor] Unable to retrieve data
2020-05-18 08:14:39 ERROR (SyncWorker_19) [homeassistant.components.rest.sensor] Error fetching data: http://www.bom.gov.au/vic/forecasts/melbourne.shtml failed with ('Connection aborted.', ConnectionResetError(104, 'Connection reset by peer'))
2020-05-18 08:14:39 ERROR (SyncWorker_19) [homeassistant.components.scrape.sensor] Unable to retrieve data
2020-05-18 10:14:41 ERROR (SyncWorker_5) [homeassistant.components.rest.sensor] Error fetching data: http://www.bom.gov.au/vic/forecasts/melbourne.shtml failed with ('Connection aborted.', ConnectionResetError(104, 'Connection reset by peer'))
2020-05-18 10:14:41 ERROR (SyncWorker_5) [homeassistant.components.scrape.sensor] Unable to retrieve data
2020-05-18 12:14:42 ERROR (SyncWorker_11) [homeassistant.components.rest.sensor] Error fetching data: http://www.bom.gov.au/vic/forecasts/melbourne.shtml failed with ('Connection aborted.', ConnectionResetError(104, 'Connection reset by peer'))
2020-05-18 12:14:42 ERROR (SyncWorker_11) [homeassistant.components.scrape.sensor] Unable to retrieve data
2020-05-18 14:14:44 ERROR (SyncWorker_15) [homeassistant.components.rest.sensor] Error fetching data: http://www.bom.gov.au/vic/forecasts/melbourne.shtml failed with ('Connection aborted.', ConnectionResetError(104, 'Connection reset by peer'))
2020-05-18 14:14:44 ERROR (SyncWorker_15) [homeassistant.components.scrape.sensor] Unable to retrieve data
2020-05-18 16:14:46 ERROR (SyncWorker_0) [homeassistant.components.rest.sensor] Error fetching data: http://www.bom.gov.au/vic/forecasts/melbourne.shtml failed with ('Connection aborted.', ConnectionResetError(104, 'Connection reset by peer'))
2020-05-18 16:14:46 ERROR (SyncWorker_0) [homeassistant.components.scrape.sensor] Unable to retrieve data
2020-05-18 18:14:48 ERROR (SyncWorker_17) [homeassistant.components.rest.sensor] Error fetching data: http://www.bom.gov.au/vic/forecasts/melbourne.shtml failed with ('Connection aborted.', ConnectionResetError(104, 'Connection reset by peer'))
2020-05-18 18:14:48 ERROR (SyncWorker_17) [homeassistant.components.scrape.sensor] Unable to retrieve data
2020-05-18 18:44:38 WARNING (MainThread) [homeassistant.helpers.entity] Update of sensor.lastest_raspbian_release is taking over 10 seconds
2020-05-18 18:44:38 ERROR (SyncWorker_4) [homeassistant.components.rest.sensor] Error fetching data: http://downloads.raspberrypi.org/raspbian/release_notes.txt failed with HTTPConnectionPool(host='downloads.raspberrypi.org', port=80): Read timed out. (read timeout=10)
2020-05-18 18:54:45 ERROR (MainThread) [aiohttp.server] Error handling request
Traceback (most recent call last):
  File "/usr/local/lib/python3.7/site-packages/urllib3/connection.py", line 160, in _new_conn
    (self._dns_host, self.port), self.timeout, **extra_kw
  File "/usr/local/lib/python3.7/site-packages/urllib3/util/connection.py", line 84, in create_connection
    raise err
  File "/usr/local/lib/python3.7/site-packages/urllib3/util/connection.py", line 74, in create_connection
    sock.connect(sa)
ConnectionRefusedError: [Errno 111] Connection refused

During handling of the above exception, another exception occurred:

Traceback (most recent call last):
  File "/usr/local/lib/python3.7/site-packages/urllib3/connectionpool.py", line 677, in urlopen
    chunked=chunked,
  File "/usr/local/lib/python3.7/site-packages/urllib3/connectionpool.py", line 392, in _make_request
    conn.request(method, url, **httplib_request_kw)
  File "/usr/local/lib/python3.7/http/client.py", line 1252, in request
    self._send_request(method, url, body, headers, encode_chunked)
  File "/usr/local/lib/python3.7/http/client.py", line 1298, in _send_request
    self.endheaders(body, encode_chunked=encode_chunked)
  File "/usr/local/lib/python3.7/http/client.py", line 1247, in endheaders
    self._send_output(message_body, encode_chunked=encode_chunked)
  File "/usr/local/lib/python3.7/http/client.py", line 1026, in _send_output
    self.send(msg)
  File "/usr/local/lib/python3.7/http/client.py", line 966, in send
    self.connect()
  File "/usr/local/lib/python3.7/site-packages/urllib3/connection.py", line 187, in connect
    conn = self._new_conn()
  File "/usr/local/lib/python3.7/site-packages/urllib3/connection.py", line 172, in _new_conn
    self, "Failed to establish a new connection: %s" % e
urllib3.exceptions.NewConnectionError: <urllib3.connection.HTTPConnection object at 0x65346af0>: Failed to establish a new connection: [Errno 111] Connection refused

During handling of the above exception, another exception occurred:

Traceback (most recent call last):
  File "/usr/local/lib/python3.7/site-packages/requests/adapters.py", line 449, in send
    timeout=timeout
  File "/usr/local/lib/python3.7/site-packages/urllib3/connectionpool.py", line 725, in urlopen
    method, url, error=e, _pool=self, _stacktrace=sys.exc_info()[2]
  File "/usr/local/lib/python3.7/site-packages/urllib3/util/retry.py", line 439, in increment
    raise MaxRetryError(_pool, url, error or ResponseError(cause))
urllib3.exceptions.MaxRetryError: HTTPConnectionPool(host='192.168.20.84', port=8080): Max retries exceeded with url: /?action=stream (Caused by NewConnectionError('<urllib3.connection.HTTPConnection object at 0x65346af0>: Failed to establish a new connection: [Errno 111] Connection refused'))

During handling of the above exception, another exception occurred:

Traceback (most recent call last):
  File "/usr/local/lib/python3.7/site-packages/aiohttp/web_protocol.py", line 418, in start
    resp = await task
  File "/usr/local/lib/python3.7/site-packages/aiohttp/web_app.py", line 458, in _handle
    resp = await handler(request)
  File "/usr/local/lib/python3.7/site-packages/aiohttp/web_middlewares.py", line 119, in impl
    return await handler(request)
  File "/usr/src/homeassistant/homeassistant/components/http/real_ip.py", line 39, in real_ip_middleware
    return await handler(request)
  File "/usr/src/homeassistant/homeassistant/components/http/ban.py", line 73, in ban_middleware
    return await handler(request)
  File "/usr/src/homeassistant/homeassistant/components/http/auth.py", line 127, in auth_middleware
    return await handler(request)
  File "/usr/src/homeassistant/homeassistant/components/http/view.py", line 125, in handle
    result = await result
  File "/usr/src/homeassistant/homeassistant/components/camera/__init__.py", line 490, in get
    return await self.handle(request, camera)
  File "/usr/src/homeassistant/homeassistant/components/camera/__init__.py", line 507, in handle
    image = await camera.async_camera_image()
  File "/usr/src/homeassistant/homeassistant/components/mjpeg/camera.py", line 113, in async_camera_image
    image = await self.hass.async_add_job(self.camera_image)
  File "/usr/local/lib/python3.7/concurrent/futures/thread.py", line 57, in run
    result = self.fn(*self.args, **self.kwargs)
  File "/usr/src/homeassistant/homeassistant/components/mjpeg/camera.py", line 145, in camera_image
    req = requests.get(self._mjpeg_url, stream=True, timeout=10)
  File "/usr/local/lib/python3.7/site-packages/requests/api.py", line 76, in get
    return request('get', url, params=params, **kwargs)
  File "/usr/local/lib/python3.7/site-packages/requests/api.py", line 61, in request
    return session.request(method=method, url=url, **kwargs)
  File "/usr/local/lib/python3.7/site-packages/requests/sessions.py", line 530, in request
    resp = self.send(prep, **send_kwargs)
  File "/usr/local/lib/python3.7/site-packages/requests/sessions.py", line 643, in send
    r = adapter.send(request, **kwargs)
  File "/usr/local/lib/python3.7/site-packages/requests/adapters.py", line 516, in send
    raise ConnectionError(e, request=request)
requests.exceptions.ConnectionError: HTTPConnectionPool(host='192.168.20.84', port=8080): Max retries exceeded with url: /?action=stream (Caused by NewConnectionError('<urllib3.connection.HTTPConnection object at 0x65346af0>: Failed to establish a new connection: [Errno 111] Connection refused'))
2020-05-18 18:54:54 ERROR (MainThread) [aiohttp.server] Error handling request
Traceback (most recent call last):
  File "/usr/local/lib/python3.7/site-packages/urllib3/connection.py", line 160, in _new_conn
    (self._dns_host, self.port), self.timeout, **extra_kw
  File "/usr/local/lib/python3.7/site-packages/urllib3/util/connection.py", line 84, in create_connection
    raise err
  File "/usr/local/lib/python3.7/site-packages/urllib3/util/connection.py", line 74, in create_connection
    sock.connect(sa)
ConnectionRefusedError: [Errno 111] Connection refused

During handling of the above exception, another exception occurred:

Traceback (most recent call last):
  File "/usr/local/lib/python3.7/site-packages/urllib3/connectionpool.py", line 677, in urlopen
    chunked=chunked,
  File "/usr/local/lib/python3.7/site-packages/urllib3/connectionpool.py", line 392, in _make_request
    conn.request(method, url, **httplib_request_kw)
  File "/usr/local/lib/python3.7/http/client.py", line 1252, in request
    self._send_request(method, url, body, headers, encode_chunked)
  File "/usr/local/lib/python3.7/http/client.py", line 1298, in _send_request
    self.endheaders(body, encode_chunked=encode_chunked)
  File "/usr/local/lib/python3.7/http/client.py", line 1247, in endheaders
    self._send_output(message_body, encode_chunked=encode_chunked)
  File "/usr/local/lib/python3.7/http/client.py", line 1026, in _send_output
    self.send(msg)
  File "/usr/local/lib/python3.7/http/client.py", line 966, in send
    self.connect()
  File "/usr/local/lib/python3.7/site-packages/urllib3/connection.py", line 187, in connect
    conn = self._new_conn()
  File "/usr/local/lib/python3.7/site-packages/urllib3/connection.py", line 172, in _new_conn
    self, "Failed to establish a new connection: %s" % e
urllib3.exceptions.NewConnectionError: <urllib3.connection.HTTPConnection object at 0x62544f70>: Failed to establish a new connection: [Errno 111] Connection refused

During handling of the above exception, another exception occurred:

Traceback (most recent call last):
  File "/usr/local/lib/python3.7/site-packages/requests/adapters.py", line 449, in send
    timeout=timeout
  File "/usr/local/lib/python3.7/site-packages/urllib3/connectionpool.py", line 725, in urlopen
    method, url, error=e, _pool=self, _stacktrace=sys.exc_info()[2]
  File "/usr/local/lib/python3.7/site-packages/urllib3/util/retry.py", line 439, in increment
    raise MaxRetryError(_pool, url, error or ResponseError(cause))
urllib3.exceptions.MaxRetryError: HTTPConnectionPool(host='192.168.20.84', port=8080): Max retries exceeded with url: /?action=stream (Caused by NewConnectionError('<urllib3.connection.HTTPConnection object at 0x62544f70>: Failed to establish a new connection: [Errno 111] Connection refused'))

During handling of the above exception, another exception occurred:

Traceback (most recent call last):
  File "/usr/local/lib/python3.7/site-packages/aiohttp/web_protocol.py", line 418, in start
    resp = await task
  File "/usr/local/lib/python3.7/site-packages/aiohttp/web_app.py", line 458, in _handle
    resp = await handler(request)
  File "/usr/local/lib/python3.7/site-packages/aiohttp/web_middlewares.py", line 119, in impl
    return await handler(request)
  File "/usr/src/homeassistant/homeassistant/components/http/real_ip.py", line 39, in real_ip_middleware
    return await handler(request)
  File "/usr/src/homeassistant/homeassistant/components/http/ban.py", line 73, in ban_middleware
    return await handler(request)
  File "/usr/src/homeassistant/homeassistant/components/http/auth.py", line 127, in auth_middleware
    return await handler(request)
  File "/usr/src/homeassistant/homeassistant/components/http/view.py", line 125, in handle
    result = await result
  File "/usr/src/homeassistant/homeassistant/components/camera/__init__.py", line 490, in get
    return await self.handle(request, camera)
  File "/usr/src/homeassistant/homeassistant/components/camera/__init__.py", line 507, in handle
    image = await camera.async_camera_image()
  File "/usr/src/homeassistant/homeassistant/components/mjpeg/camera.py", line 113, in async_camera_image
    image = await self.hass.async_add_job(self.camera_image)
  File "/usr/local/lib/python3.7/concurrent/futures/thread.py", line 57, in run
    result = self.fn(*self.args, **self.kwargs)
  File "/usr/src/homeassistant/homeassistant/components/mjpeg/camera.py", line 145, in camera_image
    req = requests.get(self._mjpeg_url, stream=True, timeout=10)
  File "/usr/local/lib/python3.7/site-packages/requests/api.py", line 76, in get
    return request('get', url, params=params, **kwargs)
  File "/usr/local/lib/python3.7/site-packages/requests/api.py", line 61, in request
    return session.request(method=method, url=url, **kwargs)
  File "/usr/local/lib/python3.7/site-packages/requests/sessions.py", line 530, in request
    resp = self.send(prep, **send_kwargs)
  File "/usr/local/lib/python3.7/site-packages/requests/sessions.py", line 643, in send
    r = adapter.send(request, **kwargs)
  File "/usr/local/lib/python3.7/site-packages/requests/adapters.py", line 516, in send
    raise ConnectionError(e, request=request)
requests.exceptions.ConnectionError: HTTPConnectionPool(host='192.168.20.84', port=8080): Max retries exceeded with url: /?action=stream (Caused by NewConnectionError('<urllib3.connection.HTTPConnection object at 0x62544f70>: Failed to establish a new connection: [Errno 111] Connection refused'))
2020-05-18 18:55:00 WARNING (MainThread) [haffmpeg.tools] Timeout reading image.
2020-05-18 18:55:14 ERROR (MainThread) [aiohttp.server] Error handling request
Traceback (most recent call last):
  File "/usr/local/lib/python3.7/site-packages/urllib3/connection.py", line 160, in _new_conn
    (self._dns_host, self.port), self.timeout, **extra_kw
  File "/usr/local/lib/python3.7/site-packages/urllib3/util/connection.py", line 84, in create_connection
    raise err
  File "/usr/local/lib/python3.7/site-packages/urllib3/util/connection.py", line 74, in create_connection
    sock.connect(sa)
ConnectionRefusedError: [Errno 111] Connection refused

During handling of the above exception, another exception occurred:

Traceback (most recent call last):
  File "/usr/local/lib/python3.7/site-packages/urllib3/connectionpool.py", line 677, in urlopen
    chunked=chunked,
  File "/usr/local/lib/python3.7/site-packages/urllib3/connectionpool.py", line 392, in _make_request
    conn.request(method, url, **httplib_request_kw)
  File "/usr/local/lib/python3.7/http/client.py", line 1252, in request
    self._send_request(method, url, body, headers, encode_chunked)
  File "/usr/local/lib/python3.7/http/client.py", line 1298, in _send_request
    self.endheaders(body, encode_chunked=encode_chunked)
  File "/usr/local/lib/python3.7/http/client.py", line 1247, in endheaders
    self._send_output(message_body, encode_chunked=encode_chunked)
  File "/usr/local/lib/python3.7/http/client.py", line 1026, in _send_output
    self.send(msg)
  File "/usr/local/lib/python3.7/http/client.py", line 966, in send
    self.connect()
  File "/usr/local/lib/python3.7/site-packages/urllib3/connection.py", line 187, in connect
    conn = self._new_conn()
  File "/usr/local/lib/python3.7/site-packages/urllib3/connection.py", line 172, in _new_conn
    self, "Failed to establish a new connection: %s" % e
urllib3.exceptions.NewConnectionError: <urllib3.connection.HTTPConnection object at 0x653193d0>: Failed to establish a new connection: [Errno 111] Connection refused

During handling of the above exception, another exception occurred:

Traceback (most recent call last):
  File "/usr/local/lib/python3.7/site-packages/requests/adapters.py", line 449, in send
    timeout=timeout
  File "/usr/local/lib/python3.7/site-packages/urllib3/connectionpool.py", line 725, in urlopen
    method, url, error=e, _pool=self, _stacktrace=sys.exc_info()[2]
  File "/usr/local/lib/python3.7/site-packages/urllib3/util/retry.py", line 439, in increment
    raise MaxRetryError(_pool, url, error or ResponseError(cause))
urllib3.exceptions.MaxRetryError: HTTPConnectionPool(host='192.168.20.84', port=8080): Max retries exceeded with url: /?action=stream (Caused by NewConnectionError('<urllib3.connection.HTTPConnection object at 0x653193d0>: Failed to establish a new connection: [Errno 111] Connection refused'))

During handling of the above exception, another exception occurred:

Traceback (most recent call last):
  File "/usr/local/lib/python3.7/site-packages/aiohttp/web_protocol.py", line 418, in start
    resp = await task
  File "/usr/local/lib/python3.7/site-packages/aiohttp/web_app.py", line 458, in _handle
    resp = await handler(request)
  File "/usr/local/lib/python3.7/site-packages/aiohttp/web_middlewares.py", line 119, in impl
    return await handler(request)
  File "/usr/src/homeassistant/homeassistant/components/http/real_ip.py", line 39, in real_ip_middleware
    return await handler(request)
  File "/usr/src/homeassistant/homeassistant/components/http/ban.py", line 73, in ban_middleware
    return await handler(request)
  File "/usr/src/homeassistant/homeassistant/components/http/auth.py", line 127, in auth_middleware
    return await handler(request)
  File "/usr/src/homeassistant/homeassistant/components/http/view.py", line 125, in handle
    result = await result
  File "/usr/src/homeassistant/homeassistant/components/camera/__init__.py", line 490, in get
    return await self.handle(request, camera)
  File "/usr/src/homeassistant/homeassistant/components/camera/__init__.py", line 507, in handle
    image = await camera.async_camera_image()
  File "/usr/src/homeassistant/homeassistant/components/mjpeg/camera.py", line 113, in async_camera_image
    image = await self.hass.async_add_job(self.camera_image)
  File "/usr/local/lib/python3.7/concurrent/futures/thread.py", line 57, in run
    result = self.fn(*self.args, **self.kwargs)
  File "/usr/src/homeassistant/homeassistant/components/mjpeg/camera.py", line 145, in camera_image
    req = requests.get(self._mjpeg_url, stream=True, timeout=10)
  File "/usr/local/lib/python3.7/site-packages/requests/api.py", line 76, in get
    return request('get', url, params=params, **kwargs)
  File "/usr/local/lib/python3.7/site-packages/requests/api.py", line 61, in request
    return session.request(method=method, url=url, **kwargs)
  File "/usr/local/lib/python3.7/site-packages/requests/sessions.py", line 530, in request
    resp = self.send(prep, **send_kwargs)
  File "/usr/local/lib/python3.7/site-packages/requests/sessions.py", line 643, in send
    r = adapter.send(request, **kwargs)
  File "/usr/local/lib/python3.7/site-packages/requests/adapters.py", line 516, in send
    raise ConnectionError(e, request=request)
requests.exceptions.ConnectionError: HTTPConnectionPool(host='192.168.20.84', port=8080): Max retries exceeded with url: /?action=stream (Caused by NewConnectionError('<urllib3.connection.HTTPConnection object at 0x653193d0>: Failed to establish a new connection: [Errno 111] Connection refused'))
2020-05-18 19:11:59 WARNING (MainThread) [homeassistant.helpers.entity] Update of sensor.lastest_raspbian_release is taking over 10 seconds
2020-05-18 19:11:59 ERROR (SyncWorker_17) [homeassistant.components.rest.sensor] Error fetching data: http://downloads.raspberrypi.org/raspbian/release_notes.txt failed with HTTPConnectionPool(host='downloads.raspberrypi.org', port=80): Read timed out. (read timeout=10)
2020-05-18 19:19:23 WARNING (MainThread) [homeassistant.helpers.entity] Update of sensor.vix is taking over 10 seconds
2020-05-18 19:19:44 ERROR (MainThread) [homeassistant.helpers.entity] Update for sensor.vix fails
Traceback (most recent call last):
  File "/usr/src/homeassistant/homeassistant/helpers/entity.py", line 279, in async_update_ha_state
    await self.async_device_update()
  File "/usr/src/homeassistant/homeassistant/helpers/entity.py", line 472, in async_device_update
    await self.hass.async_add_executor_job(self.update)
  File "/usr/local/lib/python3.7/concurrent/futures/thread.py", line 57, in run
    result = self.fn(*self.args, **self.kwargs)
  File "/usr/src/homeassistant/homeassistant/components/alpha_vantage/sensor.py", line 154, in update
    all_values, _ = self._timeseries.get_intraday(self._symbol)
  File "/usr/local/lib/python3.7/site-packages/alpha_vantage/alphavantage.py", line 174, in _format_wrapper
    self, *args, **kwargs)
  File "/usr/local/lib/python3.7/site-packages/alpha_vantage/alphavantage.py", line 159, in _call_wrapper
    return self._handle_api_call(url), data_key, meta_data_key
  File "/usr/local/lib/python3.7/site-packages/alpha_vantage/alphavantage.py", line 287, in _handle_api_call
    json_response = response.json()
  File "/usr/local/lib/python3.7/site-packages/requests/models.py", line 898, in json
    return complexjson.loads(self.text, **kwargs)
  File "/usr/local/lib/python3.7/site-packages/simplejson/__init__.py", line 525, in loads
    return _default_decoder.decode(s)
  File "/usr/local/lib/python3.7/site-packages/simplejson/decoder.py", line 370, in decode
    obj, end = self.raw_decode(s)
  File "/usr/local/lib/python3.7/site-packages/simplejson/decoder.py", line 400, in raw_decode
    return self.scan_once(s, idx=_w(s, idx).end())
simplejson.errors.JSONDecodeError: Expecting value: line 1 column 1 (char 0)
2020-05-18 20:14:49 ERROR (SyncWorker_3) [homeassistant.components.rest.sensor] Error fetching data: http://www.bom.gov.au/vic/forecasts/melbourne.shtml failed with ('Connection aborted.', ConnectionResetError(104, 'Connection reset by peer'))
2020-05-18 20:14:49 ERROR (SyncWorker_3) [homeassistant.components.scrape.sensor] Unable to retrieve data
2020-05-18 20:21:14 WARNING (MainThread) [homeassistant.helpers.entity] Update of sensor.command_sensor is taking over 10 seconds
2020-05-18 20:21:15 WARNING (MainThread) [homeassistant.components.sensor] Updating command_line sensor took longer than the scheduled update interval 0:00:10
2020-05-18 20:21:19 ERROR (SyncWorker_4) [homeassistant.components.command_line.sensor] Timeout for command: curl -i http://mohangupta-652eb883.localhost.run | head -1
2020-05-18 20:38:27 WARNING (MainThread) [homeassistant.helpers.entity] Update of sensor.command_sensor is taking over 10 seconds
2020-05-18 20:38:28 WARNING (MainThread) [homeassistant.components.sensor] Updating command_line sensor took longer than the scheduled update interval 0:00:10
2020-05-18 20:38:32 ERROR (SyncWorker_3) [homeassistant.components.command_line.sensor] Timeout for command: curl -i http://mohangupta-652eb883.localhost.run | head -1
2020-05-18 22:14:51 ERROR (SyncWorker_0) [homeassistant.components.rest.sensor] Error fetching data: http://www.bom.gov.au/vic/forecasts/melbourne.shtml failed with ('Connection aborted.', ConnectionResetError(104, 'Connection reset by peer'))
2020-05-18 22:14:51 ERROR (SyncWorker_0) [homeassistant.components.scrape.sensor] Unable to retrieve data
2020-05-18 22:15:47 ERROR (MainThread) [aiohttp.server] Error handling request
Traceback (most recent call last):
  File "/usr/local/lib/python3.7/site-packages/urllib3/connection.py", line 160, in _new_conn
    (self._dns_host, self.port), self.timeout, **extra_kw
  File "/usr/local/lib/python3.7/site-packages/urllib3/util/connection.py", line 84, in create_connection
    raise err
  File "/usr/local/lib/python3.7/site-packages/urllib3/util/connection.py", line 74, in create_connection
    sock.connect(sa)
ConnectionRefusedError: [Errno 111] Connection refused

During handling of the above exception, another exception occurred:

Traceback (most recent call last):
  File "/usr/local/lib/python3.7/site-packages/urllib3/connectionpool.py", line 677, in urlopen
    chunked=chunked,
  File "/usr/local/lib/python3.7/site-packages/urllib3/connectionpool.py", line 392, in _make_request
    conn.request(method, url, **httplib_request_kw)
  File "/usr/local/lib/python3.7/http/client.py", line 1252, in request
    self._send_request(method, url, body, headers, encode_chunked)
  File "/usr/local/lib/python3.7/http/client.py", line 1298, in _send_request
    self.endheaders(body, encode_chunked=encode_chunked)
  File "/usr/local/lib/python3.7/http/client.py", line 1247, in endheaders
    self._send_output(message_body, encode_chunked=encode_chunked)
  File "/usr/local/lib/python3.7/http/client.py", line 1026, in _send_output
    self.send(msg)
  File "/usr/local/lib/python3.7/http/client.py", line 966, in send
    self.connect()
  File "/usr/local/lib/python3.7/site-packages/urllib3/connection.py", line 187, in connect
    conn = self._new_conn()
  File "/usr/local/lib/python3.7/site-packages/urllib3/connection.py", line 172, in _new_conn
    self, "Failed to establish a new connection: %s" % e
urllib3.exceptions.NewConnectionError: <urllib3.connection.HTTPConnection object at 0x624d1550>: Failed to establish a new connection: [Errno 111] Connection refused

During handling of the above exception, another exception occurred:

Traceback (most recent call last):
  File "/usr/local/lib/python3.7/site-packages/requests/adapters.py", line 449, in send
    timeout=timeout
  File "/usr/local/lib/python3.7/site-packages/urllib3/connectionpool.py", line 725, in urlopen
    method, url, error=e, _pool=self, _stacktrace=sys.exc_info()[2]
  File "/usr/local/lib/python3.7/site-packages/urllib3/util/retry.py", line 439, in increment
    raise MaxRetryError(_pool, url, error or ResponseError(cause))
urllib3.exceptions.MaxRetryError: HTTPConnectionPool(host='192.168.20.84', port=8080): Max retries exceeded with url: /?action=stream (Caused by NewConnectionError('<urllib3.connection.HTTPConnection object at 0x624d1550>: Failed to establish a new connection: [Errno 111] Connection refused'))

During handling of the above exception, another exception occurred:

Traceback (most recent call last):
  File "/usr/local/lib/python3.7/site-packages/aiohttp/web_protocol.py", line 418, in start
    resp = await task
  File "/usr/local/lib/python3.7/site-packages/aiohttp/web_app.py", line 458, in _handle
    resp = await handler(request)
  File "/usr/local/lib/python3.7/site-packages/aiohttp/web_middlewares.py", line 119, in impl
    return await handler(request)
  File "/usr/src/homeassistant/homeassistant/components/http/real_ip.py", line 39, in real_ip_middleware
    return await handler(request)
  File "/usr/src/homeassistant/homeassistant/components/http/ban.py", line 73, in ban_middleware
    return await handler(request)
  File "/usr/src/homeassistant/homeassistant/components/http/auth.py", line 127, in auth_middleware
    return await handler(request)
  File "/usr/src/homeassistant/homeassistant/components/http/view.py", line 125, in handle
    result = await result
  File "/usr/src/homeassistant/homeassistant/components/camera/__init__.py", line 490, in get
    return await self.handle(request, camera)
  File "/usr/src/homeassistant/homeassistant/components/camera/__init__.py", line 507, in handle
    image = await camera.async_camera_image()
  File "/usr/src/homeassistant/homeassistant/components/mjpeg/camera.py", line 113, in async_camera_image
    image = await self.hass.async_add_job(self.camera_image)
  File "/usr/local/lib/python3.7/concurrent/futures/thread.py", line 57, in run
    result = self.fn(*self.args, **self.kwargs)
  File "/usr/src/homeassistant/homeassistant/components/mjpeg/camera.py", line 145, in camera_image
    req = requests.get(self._mjpeg_url, stream=True, timeout=10)
  File "/usr/local/lib/python3.7/site-packages/requests/api.py", line 76, in get
    return request('get', url, params=params, **kwargs)
  File "/usr/local/lib/python3.7/site-packages/requests/api.py", line 61, in request
    return session.request(method=method, url=url, **kwargs)
  File "/usr/local/lib/python3.7/site-packages/requests/sessions.py", line 530, in request
    resp = self.send(prep, **send_kwargs)
  File "/usr/local/lib/python3.7/site-packages/requests/sessions.py", line 643, in send
    r = adapter.send(request, **kwargs)
  File "/usr/local/lib/python3.7/site-packages/requests/adapters.py", line 516, in send
    raise ConnectionError(e, request=request)
requests.exceptions.ConnectionError: HTTPConnectionPool(host='192.168.20.84', port=8080): Max retries exceeded with url: /?action=stream (Caused by NewConnectionError('<urllib3.connection.HTTPConnection object at 0x624d1550>: Failed to establish a new connection: [Errno 111] Connection refused'))
2020-05-18 22:17:51 ERROR (MainThread) [aiohttp.server] Error handling request
Traceback (most recent call last):
  File "/usr/local/lib/python3.7/site-packages/urllib3/connection.py", line 160, in _new_conn
    (self._dns_host, self.port), self.timeout, **extra_kw
  File "/usr/local/lib/python3.7/site-packages/urllib3/util/connection.py", line 84, in create_connection
    raise err
  File "/usr/local/lib/python3.7/site-packages/urllib3/util/connection.py", line 74, in create_connection
    sock.connect(sa)
ConnectionRefusedError: [Errno 111] Connection refused

During handling of the above exception, another exception occurred:

Traceback (most recent call last):
  File "/usr/local/lib/python3.7/site-packages/urllib3/connectionpool.py", line 677, in urlopen
    chunked=chunked,
  File "/usr/local/lib/python3.7/site-packages/urllib3/connectionpool.py", line 392, in _make_request
    conn.request(method, url, **httplib_request_kw)
  File "/usr/local/lib/python3.7/http/client.py", line 1252, in request
    self._send_request(method, url, body, headers, encode_chunked)
  File "/usr/local/lib/python3.7/http/client.py", line 1298, in _send_request
    self.endheaders(body, encode_chunked=encode_chunked)
  File "/usr/local/lib/python3.7/http/client.py", line 1247, in endheaders
    self._send_output(message_body, encode_chunked=encode_chunked)
  File "/usr/local/lib/python3.7/http/client.py", line 1026, in _send_output
    self.send(msg)
  File "/usr/local/lib/python3.7/http/client.py", line 966, in send
    self.connect()
  File "/usr/local/lib/python3.7/site-packages/urllib3/connection.py", line 187, in connect
    conn = self._new_conn()
  File "/usr/local/lib/python3.7/site-packages/urllib3/connection.py", line 172, in _new_conn
    self, "Failed to establish a new connection: %s" % e
urllib3.exceptions.NewConnectionError: <urllib3.connection.HTTPConnection object at 0x66876370>: Failed to establish a new connection: [Errno 111] Connection refused

During handling of the above exception, another exception occurred:

Traceback (most recent call last):
  File "/usr/local/lib/python3.7/site-packages/requests/adapters.py", line 449, in send
    timeout=timeout
  File "/usr/local/lib/python3.7/site-packages/urllib3/connectionpool.py", line 725, in urlopen
    method, url, error=e, _pool=self, _stacktrace=sys.exc_info()[2]
  File "/usr/local/lib/python3.7/site-packages/urllib3/util/retry.py", line 439, in increment
    raise MaxRetryError(_pool, url, error or ResponseError(cause))
urllib3.exceptions.MaxRetryError: HTTPConnectionPool(host='192.168.20.84', port=8080): Max retries exceeded with url: /?action=stream (Caused by NewConnectionError('<urllib3.connection.HTTPConnection object at 0x66876370>: Failed to establish a new connection: [Errno 111] Connection refused'))

During handling of the above exception, another exception occurred:

Traceback (most recent call last):
  File "/usr/local/lib/python3.7/site-packages/aiohttp/web_protocol.py", line 418, in start
    resp = await task
  File "/usr/local/lib/python3.7/site-packages/aiohttp/web_app.py", line 458, in _handle
    resp = await handler(request)
  File "/usr/local/lib/python3.7/site-packages/aiohttp/web_middlewares.py", line 119, in impl
    return await handler(request)
  File "/usr/src/homeassistant/homeassistant/components/http/real_ip.py", line 39, in real_ip_middleware
    return await handler(request)
  File "/usr/src/homeassistant/homeassistant/components/http/ban.py", line 73, in ban_middleware
    return await handler(request)
  File "/usr/src/homeassistant/homeassistant/components/http/auth.py", line 127, in auth_middleware
    return await handler(request)
  File "/usr/src/homeassistant/homeassistant/components/http/view.py", line 125, in handle
    result = await result
  File "/usr/src/homeassistant/homeassistant/components/camera/__init__.py", line 490, in get
    return await self.handle(request, camera)
  File "/usr/src/homeassistant/homeassistant/components/camera/__init__.py", line 507, in handle
    image = await camera.async_camera_image()
  File "/usr/src/homeassistant/homeassistant/components/mjpeg/camera.py", line 113, in async_camera_image
    image = await self.hass.async_add_job(self.camera_image)
  File "/usr/local/lib/python3.7/concurrent/futures/thread.py", line 57, in run
    result = self.fn(*self.args, **self.kwargs)
  File "/usr/src/homeassistant/homeassistant/components/mjpeg/camera.py", line 145, in camera_image
    req = requests.get(self._mjpeg_url, stream=True, timeout=10)
  File "/usr/local/lib/python3.7/site-packages/requests/api.py", line 76, in get
    return request('get', url, params=params, **kwargs)
  File "/usr/local/lib/python3.7/site-packages/requests/api.py", line 61, in request
    return session.request(method=method, url=url, **kwargs)
  File "/usr/local/lib/python3.7/site-packages/requests/sessions.py", line 530, in request
    resp = self.send(prep, **send_kwargs)
  File "/usr/local/lib/python3.7/site-packages/requests/sessions.py", line 643, in send
    r = adapter.send(request, **kwargs)
  File "/usr/local/lib/python3.7/site-packages/requests/adapters.py", line 516, in send
    raise ConnectionError(e, request=request)
requests.exceptions.ConnectionError: HTTPConnectionPool(host='192.168.20.84', port=8080): Max retries exceeded with url: /?action=stream (Caused by NewConnectionError('<urllib3.connection.HTTPConnection object at 0x66876370>: Failed to establish a new connection: [Errno 111] Connection refused'))
