2020-05-17 19:13:52 WARNING (MainThread) [homeassistant.loader] You are using a custom integration for mohan_helloworld which has not been tested by Home Assistant. This component might cause stability problems, be sure to disable it if you experience issues with Home Assistant.
2020-05-17 19:13:57 WARNING (MainThread) [homeassistant.loader] You are using a custom integration for hacs which has not been tested by Home Assistant. This component might cause stability problems, be sure to disable it if you experience issues with Home Assistant.
2020-05-17 19:13:59 WARNING (Recorder) [homeassistant.components.recorder] Ended unfinished session (id=216 from 2020-05-17 08:58:22.322731)
2020-05-17 19:14:10 WARNING (MainThread) [homeassistant.loader] You are using a custom integration for bom_forecast which has not been tested by Home Assistant. This component might cause stability problems, be sure to disable it if you experience issues with Home Assistant.
2020-05-17 19:14:14 WARNING (MainThread) [homeassistant.loader] You are using a custom integration for mohan_sensor which has not been tested by Home Assistant. This component might cause stability problems, be sure to disable it if you experience issues with Home Assistant.
2020-05-17 19:14:22 WARNING (MainThread) [homeassistant.components.mobile_app.notify] Found duplicate device name Aruna Gupta’s iPhone
2020-05-17 19:14:22 WARNING (MainThread) [homeassistant.components.mobile_app.notify] Found duplicate device name Aruna Gupta’s iPhone
2020-05-17 19:14:22 WARNING (MainThread) [homeassistant.components.mobile_app.notify] Found duplicate device name Aruna Gupta’s iPhone
2020-05-17 19:14:22 WARNING (MainThread) [homeassistant.components.mobile_app.notify] Found duplicate device name Aruna Gupta’s iPhone
2020-05-17 19:14:25 WARNING (MainThread) [homeassistant.components.weather] Setup of weather platform met is taking over 10 seconds.
2020-05-17 19:14:39 WARNING (MainThread) [homeassistant.helpers.translation] hacs: the '.translations' directory has been moved, the new name is 'translations', starting with Home Assistant 0.111 your translations will no longer load if you do not move/rename this 
2020-05-17 19:14:42 WARNING (MainThread) [homeassistant.helpers.translation] hacs: the '.translations' directory has been moved, the new name is 'translations', starting with Home Assistant 0.111 your translations will no longer load if you do not move/rename this 
2020-05-17 19:14:54 WARNING (MainThread) [homeassistant.helpers.translation] hacs: the '.translations' directory has been moved, the new name is 'translations', starting with Home Assistant 0.111 your translations will no longer load if you do not move/rename this 
2020-05-17 19:15:32 ERROR (Recorder) [homeassistant.components.recorder] Error adding event: (sqlite3.OperationalError) database is locked
(Background on this error at: http://sqlalche.me/e/e3q8)
Traceback (most recent call last):
  File "/usr/local/lib/python3.7/site-packages/sqlalchemy/engine/base.py", line 2285, in _wrap_pool_connect
    return fn()
  File "/usr/local/lib/python3.7/site-packages/sqlalchemy/pool/base.py", line 363, in connect
    return _ConnectionFairy._checkout(self)
  File "/usr/local/lib/python3.7/site-packages/sqlalchemy/pool/base.py", line 773, in _checkout
    fairy = _ConnectionRecord.checkout(pool)
  File "/usr/local/lib/python3.7/site-packages/sqlalchemy/pool/base.py", line 492, in checkout
    rec = pool._do_get()
  File "/usr/local/lib/python3.7/site-packages/sqlalchemy/pool/impl.py", line 238, in _do_get
    return self._create_connection()
  File "/usr/local/lib/python3.7/site-packages/sqlalchemy/pool/base.py", line 308, in _create_connection
    return _ConnectionRecord(self)
  File "/usr/local/lib/python3.7/site-packages/sqlalchemy/pool/base.py", line 437, in __init__
    self.__connect(first_connect_check=True)
  File "/usr/local/lib/python3.7/site-packages/sqlalchemy/pool/base.py", line 664, in __connect
    pool.dispatch.connect(self.connection, self)
  File "/usr/local/lib/python3.7/site-packages/sqlalchemy/event/attr.py", line 322, in __call__
    fn(*args, **kw)
  File "/usr/src/homeassistant/homeassistant/components/recorder/__init__.py", line 499, in setup_recorder_connection
    cursor.execute("PRAGMA journal_mode=WAL")
sqlite3.OperationalError: database is locked

The above exception was the direct cause of the following exception:

Traceback (most recent call last):
  File "/usr/src/homeassistant/homeassistant/components/recorder/__init__.py", line 372, in run
    self.event_session.flush()
  File "/usr/local/lib/python3.7/site-packages/sqlalchemy/orm/session.py", line 2496, in flush
    self._flush(objects)
  File "/usr/local/lib/python3.7/site-packages/sqlalchemy/orm/session.py", line 2637, in _flush
    transaction.rollback(_capture_exception=True)
  File "/usr/local/lib/python3.7/site-packages/sqlalchemy/util/langhelpers.py", line 69, in __exit__
    exc_value, with_traceback=exc_tb,
  File "/usr/local/lib/python3.7/site-packages/sqlalchemy/util/compat.py", line 178, in raise_
    raise exception
  File "/usr/local/lib/python3.7/site-packages/sqlalchemy/orm/session.py", line 2597, in _flush
    flush_context.execute()
  File "/usr/local/lib/python3.7/site-packages/sqlalchemy/orm/unitofwork.py", line 422, in execute
    rec.execute(self)
  File "/usr/local/lib/python3.7/site-packages/sqlalchemy/orm/unitofwork.py", line 589, in execute
    uow,
  File "/usr/local/lib/python3.7/site-packages/sqlalchemy/orm/persistence.py", line 213, in save_obj
    ) in _organize_states_for_save(base_mapper, states, uowtransaction):
  File "/usr/local/lib/python3.7/site-packages/sqlalchemy/orm/persistence.py", line 374, in _organize_states_for_save
    base_mapper, uowtransaction, states
  File "/usr/local/lib/python3.7/site-packages/sqlalchemy/orm/persistence.py", line 1602, in _connections_for_states
    connection = uowtransaction.transaction.connection(base_mapper)
  File "/usr/local/lib/python3.7/site-packages/sqlalchemy/orm/session.py", line 313, in connection
    return self._connection_for_bind(bind, execution_options)
  File "/usr/local/lib/python3.7/site-packages/sqlalchemy/orm/session.py", line 420, in _connection_for_bind
    conn = self._parent._connection_for_bind(bind, execution_options)
  File "/usr/local/lib/python3.7/site-packages/sqlalchemy/orm/session.py", line 432, in _connection_for_bind
    conn = bind._contextual_connect()
  File "/usr/local/lib/python3.7/site-packages/sqlalchemy/engine/base.py", line 2251, in _contextual_connect
    self._wrap_pool_connect(self.pool.connect, None),
  File "/usr/local/lib/python3.7/site-packages/sqlalchemy/engine/base.py", line 2289, in _wrap_pool_connect
    e, dialect, self
  File "/usr/local/lib/python3.7/site-packages/sqlalchemy/engine/base.py", line 1555, in _handle_dbapi_exception_noconnection
    sqlalchemy_exception, with_traceback=exc_info[2], from_=e
  File "/usr/local/lib/python3.7/site-packages/sqlalchemy/util/compat.py", line 178, in raise_
    raise exception
  File "/usr/local/lib/python3.7/site-packages/sqlalchemy/engine/base.py", line 2285, in _wrap_pool_connect
    return fn()
  File "/usr/local/lib/python3.7/site-packages/sqlalchemy/pool/base.py", line 363, in connect
    return _ConnectionFairy._checkout(self)
  File "/usr/local/lib/python3.7/site-packages/sqlalchemy/pool/base.py", line 773, in _checkout
    fairy = _ConnectionRecord.checkout(pool)
  File "/usr/local/lib/python3.7/site-packages/sqlalchemy/pool/base.py", line 492, in checkout
    rec = pool._do_get()
  File "/usr/local/lib/python3.7/site-packages/sqlalchemy/pool/impl.py", line 238, in _do_get
    return self._create_connection()
  File "/usr/local/lib/python3.7/site-packages/sqlalchemy/pool/base.py", line 308, in _create_connection
    return _ConnectionRecord(self)
  File "/usr/local/lib/python3.7/site-packages/sqlalchemy/pool/base.py", line 437, in __init__
    self.__connect(first_connect_check=True)
  File "/usr/local/lib/python3.7/site-packages/sqlalchemy/pool/base.py", line 664, in __connect
    pool.dispatch.connect(self.connection, self)
  File "/usr/local/lib/python3.7/site-packages/sqlalchemy/event/attr.py", line 322, in __call__
    fn(*args, **kw)
  File "/usr/src/homeassistant/homeassistant/components/recorder/__init__.py", line 499, in setup_recorder_connection
    cursor.execute("PRAGMA journal_mode=WAL")
sqlalchemy.exc.OperationalError: (sqlite3.OperationalError) database is locked
(Background on this error at: http://sqlalche.me/e/e3q8)
2020-05-17 19:15:39 ERROR (Recorder) [homeassistant.components.recorder] Error executing query: This Session's transaction has been rolled back due to a previous exception during flush. To begin a new transaction with this Session, first issue Session.rollback(). Original exception was: (sqlite3.OperationalError) database is locked
(Background on this error at: http://sqlalche.me/e/e3q8) (Background on this error at: http://sqlalche.me/e/7s2a)
2020-05-17 19:15:41 ERROR (Recorder) [homeassistant.components.recorder] Error saving events: This Session's transaction has been rolled back due to a previous exception during flush. To begin a new transaction with this Session, first issue Session.rollback(). Original exception was: (sqlite3.OperationalError) database is locked
(Background on this error at: http://sqlalche.me/e/e3q8) (Background on this error at: http://sqlalche.me/e/7s2a)
Traceback (most recent call last):
  File "/usr/src/homeassistant/homeassistant/components/recorder/__init__.py", line 419, in _commit_event_session_or_retry
    self._commit_event_session()
  File "/usr/src/homeassistant/homeassistant/components/recorder/__init__.py", line 470, in _commit_event_session
    self.event_session.commit()
  File "/usr/local/lib/python3.7/site-packages/sqlalchemy/orm/session.py", line 1036, in commit
    self.transaction.commit()
  File "/usr/local/lib/python3.7/site-packages/sqlalchemy/orm/session.py", line 501, in commit
    self._assert_active(prepared_ok=True)
  File "/usr/local/lib/python3.7/site-packages/sqlalchemy/orm/session.py", line 295, in _assert_active
    code="7s2a",
sqlalchemy.exc.InvalidRequestError: This Session's transaction has been rolled back due to a previous exception during flush. To begin a new transaction with this Session, first issue Session.rollback(). Original exception was: (sqlite3.OperationalError) database is locked
(Background on this error at: http://sqlalche.me/e/e3q8) (Background on this error at: http://sqlalche.me/e/7s2a)
2020-05-17 19:23:17 WARNING (MainThread) [homeassistant.helpers.service] Unable to find referenced entities sensor.relative_sensor
2020-05-17 19:23:24 WARNING (MainThread) [homeassistant.helpers.service] Unable to find referenced entities sensor.relative_sensor
